Workbook

Sheet README
A1: 30 Nights - balance model v1.1
A3: What this is
A4: A paper prototype of the whole game: 14 prep days + 30 nights, one row per day on the Plan sheet.
A5: You play it by filling the yellow cells; the formulas tell you whether the colony is alive on day 44.
A6: The point is to feel where the decisions are BEFORE any code exists, and to tune the numbers on Params.
A8: Sheets
A9: Plan - the day-by-day game. Summary at the top: days alive, verdict, minimum stocks, breaches.
A10: Params - every number of the world (blue). Change a value, watch the Plan recompute.
A11: People - the crew: work speed, expedition speed, carry weight, arrival day. Blank arrival = never joins.
A12: Houses - the village: shop, warehouse, clinic, garage, mine office and twelve residential houses; distance, stock, depletion.
A13: Nights - the rhythm of the siege (assault / probe / quiet), derived from Params.
A15: The rules in one breath
... A38: Generated with openpyxl without cached values: Excel computes every formula on open (press F9 if anything shows 0). All numbers are design assumptions, not sourced data.

Sheet Plan
A1: 30 Nights - balance model v1.1 (two runners a day, 17 houses, damage carries over). Paper prototype: one row = one day.
A2: Days alive | B2: =COUNTIF(AW9:AW52,">0") | D2: Verdict | E2: =IF(B2>=Params!$B$5+Params!$B$6,"SURVIVED","DEAD on day "&(B2+1)) | G2: HOW TO PLAY: fill the yellow cells day by day (hours per job, holes to repair, up to two expeditions: which house and who runs).
A3: Final health | B3: =AW52 | D3: Nights breached | E3: =COUNTIF(AU9:AU52,"BREACH") | G3: Yellow = your daily plan. Blue (Params / People / Houses) = the rules of the world. Black = formulas, do not edit.
A4: Min food | B4: =MIN(AJ9:AJ52) | D4: Cold days | E4: =COUNTIF(AV9:AV52,"<"&Params!$B$44) | G4: Negative stock or a red flag in Status = the plan breaks that day. Hours slack < 0 = overworked; daylight slack < 0 = chopping or a trip in the dark.
A5: Min fuel | B5: =MIN(AI9:AI52) | D5: Dark trips | E5: =COUNTIF(T9:T52,"DARK") | G5: Reference plan pre-filled: it survives, with the last assaults breaching. Try more houses (food up, logs down), a third mouth on People, half the stoves.
A6: Min boards | B6: =MIN(AH9:AH52) | D6: Logs chopped | E6: =SUMPRODUCT(H9:H52,F9:F52)*Params!$B$24
A7: Min logs | B7: =MIN(AG9:AG52) | D7: Spare hours (total) | E7: =SUM(V9:V52)
A8: Day | B8: Phase | C8: Night # | D8: Daylight (h) | E8: People | F8: Team work x | G8: Hours available | H8: Chop (h) | I8: Saw (h) | J8: Split (h) | K8: Repair holes (#) | L8: Reinforce (#) | M8: Build sections (#) | N8: Trip 1 house | O8: Trip 1 person | P8: Trip 2 house | Q8: Trip 2 person | R8: Trip 1 (h) | S8: Trip 2 (h) | T8: Trip check | U8: Hours used | V8: Hours slack | W8: Daylight slack | X8: Stoves lit | Y8: Carry 1 | Z8: Food haul 1 | AA8: Boards haul 1 | AB8: Meds haul 1 | AC8: Carry 2 | AD8: Food haul 2 | AE8: Boards haul 2 | AF8: Meds haul 2 | AG8: Logs | AH8: Boards | AI8: Fuel | AJ8: Food | AK8: Meds | AL8: Missing sections | AM8: Holes (before night) | AN8: Buffer hp (before) | AO8: Attackers | AP8: Damage | AQ8: Buffer hp (after) | AR8: New holes | AS8: Damage carry (hp) | AT8: Holes (after night) | AU8: Breach | AV8: Temp inside (C) | AW8: Health | AX8: Status
A9: 1 | B9: =IF(A9<=Params!$B$5,"prep","night") | C9: =MAX(0,A9-Params!$B$5) | D9: =IF(A9<=Params!$B$5,ROUND(Params!$B$7-(Params!$B$7-Params!$B$8)*(A9-1)/(Params!$B$5-1),1),0) | E9: =COUNTIFS(People!$F$2:$F$7,"<="&A9,People!$F$2:$F$7,">0") | F9: =IF(E9=0,1,SUMIFS(People!$C$2:$C$7,People!$F$2:$F$7,"<="&A9,People!$F$2:$F$7,">0")/E9) | G9: =E9*Params!$B$9 | H9: 4.6 | I9: 2 | J9: 1 | K9: 1 | L9: 0 | M9: 1 | N9: SHOP | O9: A | P9: CLINIC | Q9: B | R9: =IF(N9="",0,(2*INDEX(Houses!$D$2:$D$18,MATCH(N9,Houses!$A$2:$A$18,0))+Params!$B$57)/IF(O9="",1,INDEX(People!$D$2:$D$7,MATCH(O9,People!$A$2:$A$7,0)))) | S9: =IF(P9="",0,(2*INDEX(Houses!$D$2:$D$18,MATCH(P9,Houses!$A$2:$A$18,0))+Params!$B$57)/IF(Q9="",1,INDEX(People!$D$2:$D$7,MATCH(Q9,People!$A$2:$A$7,0)))) | T9: =IF(AND(N9="",P9=""),"",IF(MAX(R9,S9)<=D9,"ok","DARK")) | U9: =H9+I9+J9+K9*Params!$B$32+L9*Params!$B$34+M9*Params!$B$37+R9+S9 | V9: =G9-U9 | W9: =D9*E9-(H9+R9+S9) | X9: 1 | Y9: =IF(N9="",0,IF(O9="",8,INDEX(People!$E$2:$E$7,MATCH(O9,People!$A$2:$A$7,0)))) | Z9: =IF(N9="",0,MAX(0,MIN(INDEX(Houses!$E$2:$E$18,MATCH(N9,Houses!$A$2:$A$18,0))-IF(INDEX(Houses!$H$2:$H$18,MATCH(N9,Houses!$A$2:$A$18,0))=1,SUMIF($N$8:N8,N9,$Z$8:Z8)+SUMIF($P$8:P8,N9,$AD$8:AD8),0),Y9))) | AA9: =IF(N9="",0,MAX(0,MIN(INDEX(Houses!$F$2:$F$18,MATCH(N9,Houses!$A$2:$A$18,0))-IF(INDEX(Houses!$H$2:$H$18,MATCH(N9,Houses!$A$2:$A$18,0))=1,SUMIF($N$8:N8,N9,$AA$8:AA8)+SUMIF($P$8:P8,N9,$AE$8:AE8),0),INT((Y9-Z9)/2)))) | AB9: =IF(N9="",0,MAX(0,INDEX(Houses!$G$2:$G$18,MATCH(N9,Houses!$A$2:$A$18,0))-IF(INDEX(Houses!$H$2:$H$18,MATCH(N9,Houses!$A$2:$A$18,0))=1,SUMIF($N$8:N8,N9,$AB$8:AB8)+SUMIF($P$8:P8,N9,$AF$8:AF8),0))) | AC9: =IF(P9="",0,IF(Q9="",8,INDEX(People!$E$2:$E$7,MATCH(Q9,People!$A$2:$A$7,0)))) | AD9: =IF(P9="",0,MAX(0,MIN(INDEX(Houses!$E$2:$E$18,MATCH(P9,Houses!$A$2:$A$18,0))-IF(INDEX(Houses!$H$2:$H$18,MATCH(P9,Houses!$A$2:$A$18,0))=1,SUMIF($P$8:P8,P9,$AD$8:AD8)+SUMIF($N$8:N8,P9,$Z$8:Z8)+IF(N9=P9,Z9,0),0),AC9))) | AE9: =IF(P9="",0,MAX(0,MIN(INDEX(Houses!$F$2:$F$18,MATCH(P9,Houses!$A$2:$A$18,0))-IF(INDEX(Houses!$H$2:$H$18,MATCH(P9,Houses!$A$2:$A$18,0))=1,SUMIF($P$8:P8,P9,$AE$8:AE8)+SUMIF($N$8:N8,P9,$AA$8:AA8)+IF(N9=P9,AA9,0),0),INT((AC9-AD9)/2)))) | AF9: =IF(P9="",0,MAX(0,INDEX(Houses!$G$2:$G$18,MATCH(P9,Houses!$A$2:$A$18,0))-IF(INDEX(Houses!$H$2:$H$18,MATCH(P9,Houses!$A$2:$A$18,0))=1,SUMIF($P$8:P8,P9,$AF$8:AF8)+SUMIF($N$8:N8,P9,$AB$8:AB8)+IF(N9=P9,AB9,0),0))) | AG9: =Params!$B$14+H9*Params!$B$24*F9-I9*Params!$B$25-J9*Params!$B$27 | AH9: =Params!$B$13+I9*Params!$B$25*Params!$B$26-K9*Params!$B$31-L9*Params!$B$33-M9*Params!$B$36+AA9+AE9 | AI9: =Params!$B$12+J9*Params!$B$27*Params!$B$28-X9*Params!$B$43*24 | AJ9: =Params!$B$11-E9*Params!$B$22+Z9+AD9 | AK9: =Params!$B$15+AB9+AF9 | AL9: =MAX(0,Params!$B$17-M9) | AM9: =MAX(0,Params!$B$18-K9) | AN9: =Params!$B$19+L9*Params!$B$35 | AO9: =IF(C9=0,0,INDEX(Nights!$B$2:$B$31,C9)) | AP9: =AO9*Params!$B$51*Params!$B$50 | AQ9: =MAX(0,AN9-AP9) | AR9: =INT((Params!$B$20+MAX(0,AP9-AN9))/Params!$B$30) | AS9: =(Params!$B$20+MAX(0,AP9-AN9))-AR9*Params!$B$30 | AT9: =AM9+AR9 | AU9: =IF(AND(AO9>0,OR(AM9+AL9>0,AR9>0)),"BREACH","") | AV9: =Params!$B$40+IF(AI9<0,0,X9)*Params!$B$41-(AM9+AL9)*Params!$B$42 | AW9: =MAX(0,MIN(100,Params!$B$16-IF(AV9<Params!$B$44,(Params!$B$44-AV9)*Params!$B$45,0)-IF(AJ9<0,Params!$B$54,0)-IF(AU9="BREACH",Params!$B$53,0)-IF(T9="DARK",Params!$B$55,0))) | AX9: =IF(AW9<=0,"DEAD",TRIM(IF(V9<0,"OVERWORK ","")&IF(W9<0,"NO-DAYLIGHT ","")&IF(AG9<0,"NO-LOGS ","")&IF(AH9<0,"NO-BOARDS ","")&IF(AI9<0,"NO-FUEL ","")&IF(AJ9<0,"HUNGER ","")&AU9&" "&IF(T9="DARK","DARK-TRIP ","")&IF(AV9<Params!$B$44,"COLD","")))
A10: 2 | B10: =IF(A10<=Params!$B$5,"prep","night") | C10: =MAX(0,A10-Params!$B$5) | D10: =IF(A10<=Params!$B$5,ROUND(Params!$B$7-(Params!$B$7-Params!$B$8)*(A10-1)/(Params!$B$5-1),1),0) | E10: =COUNTIFS(People!$F$2:$F$7,"<="&A10,People!$F$2:$F$7,">0") | F10: =IF(E10=0,1,SUMIFS(People!$C$2:$C$7,People!$F$2:$F$7,"<="&A10,People!$F$2:$F$7,">0")/E10) | G10: =E10*Params!$B$9 | H10: 5.1 | I10: 6 | J10: 1 | K10: 1 | L10: 0 | M10: 0 | N10: SHOP | O10: A | P10: GARAGE | Q10: B | R10: =IF(N10="",0,(2*INDEX(Houses!$D$2:$D$18,MATCH(N10,Houses!$A$2:$A$18,0))+Params!$B$57)/IF(O10="",1,INDEX(People!$D$2:$D$7,MATCH(O10,People!$A$2:$A$7,0)))) | S10: =IF(P10="",0,(2*INDEX(Houses!$D$2:$D$18,MATCH(P10,Houses!$A$2:$A$18,0))+Params!$B$57)/IF(Q10="",1,INDEX(People!$D$2:$D$7,MATCH(Q10,People!$A$2:$A$7,0)))) | T10: =IF(AND(N10="",P10=""),"",IF(MAX(R10,S10)<=D10,"ok","DARK")) | U10: =H10+I10+J10+K10*Params!$B$32+L10*Params!$B$34+M10*Params!$B$37+R10+S10 | V10: =G10-U10 | W10: =D10*E10-(H10+R10+S10) | X10: 1 | Y10: =IF(N10="",0,IF(O10="",8,INDEX(People!$E$2:$E$7,MATCH(O10,People!$A$2:$A$7,0)))) | Z10: =IF(N10="",0,MAX(0,MIN(INDEX(Houses!$E$2:$E$18,MATCH(N10,Houses!$A$2:$A$18,0))-IF(INDEX(Houses!$H$2:$H$18,MATCH(N10,Houses!$A$2:$A$18,0))=1,SUMIF($N$8:N9,N10,$Z$8:Z9)+SUMIF($P$8:P9,N10,$AD$8:AD9),0),Y10))) | AA10: =IF(N10="",0,MAX(0,MIN(INDEX(Houses!$F$2:$F$18,MATCH(N10,Houses!$A$2:$A$18,0))-IF(INDEX(Houses!$H$2:$H$18,MATCH(N10,Houses!$A$2:$A$18,0))=1,SUMIF($N$8:N9,N10,$AA$8:AA9)+SUMIF($P$8:P9,N10,$AE$8:AE9),0),INT((Y10-Z10)/2)))) | AB10: =IF(N10="",0,MAX(0,INDEX(Houses!$G$2:$G$18,MATCH(N10,Houses!$A$2:$A$18,0))-IF(INDEX(Houses!$H$2:$H$18,MATCH(N10,Houses!$A$2:$A$18,0))=1,SUMIF($N$8:N9,N10,$AB$8:AB9)+SUMIF($P$8:P9,N10,$AF$8:AF9),0))) | AC10: =IF(P10="",0,IF(Q10="",8,INDEX(People!$E$2:$E$7,MATCH(Q10,People!$A$2:$A$7,0)))) | AD10: =IF(P10="",0,MAX(0,MIN(INDEX(Houses!$E$2:$E$18,MATCH(P10,Houses!$A$2:$A$18,0))-IF(INDEX(Houses!$H$2:$H$18,MATCH(P10,Houses!$A$2:$A$18,0))=1,SUMIF($P$8:P9,P10,$AD$8:AD9)+SUMIF($N$8:N9,P10,$Z$8:Z9)+IF(N10=P10,Z10,0),0),AC10))) | AE10: =IF(P10="",0,MAX(0,MIN(INDEX(Houses!$F$2:$F$18,MATCH(P10,Houses!$A$2:$A$18,0))-IF(INDEX(Houses!$H$2:$H$18,MATCH(P10,Houses!$A$2:$A$18,0))=1,SUMIF($P$8:P9,P10,$AE$8:AE9)+SUMIF($N$8:N9,P10,$AA$8:AA9)+IF(N10=P10,AA10,0),0),INT((AC10-AD10)/2)))) | AF10: =IF(P10="",0,MAX(0,INDEX(Houses!$G$2:$G$18,MATCH(P10,Houses!$A$2:$A$18,0))-IF(INDEX(Houses!$H$2:$H$18,MATCH(P10,Houses!$A$2:$A$18,0))=1,SUMIF($P$8:P9,P10,$AF$8:AF9)+SUMIF($N$8:N9,P10,$AB$8:AB9)+IF(N10=P10,AB10,0),0))) | AG10: =AG9+H10*Params!$B$24*F10-I10*Params!$B$25-J10*Params!$B$27 | AH10: =AH9+I10*Params!$B$25*Params!$B$26-K10*Params!$B$31-L10*Params!$B$33-M10*Params!$B$36+AA10+AE10 | AI10: =AI9+J10*Params!$B$27*Params!$B$28-X10*Params!$B$43*24 | AJ10: =AJ9-E10*Params!$B$22+Z10+AD10 | AK10: =AK9+AB10+AF10 | AL10: =MAX(0,AL9-M10) | AM10: =MAX(0,AT9-K10) | AN10: =AQ9+L10*Params!$B$35 | AO10: =IF(C10=0,0,INDEX(Nights!$B$2:$B$31,C10)) | AP10: =AO10*Params!$B$51*Params!$B$50 | AQ10: =MAX(0,AN10-AP10) | AR10: =INT((AS9+MAX(0,AP10-AN10))/Params!$B$30) | AS10: =(AS9+MAX(0,AP10-AN10))-AR10*Params!$B$30 | AT10: =AM10+AR10 | AU10: =IF(AND(AO10>0,OR(AM10+AL10>0,AR10>0)),"BREACH","") | AV10: =Params!$B$40+IF(AI10<0,0,X10)*Params!$B$41-(AM10+AL10)*Params!$B$42 | AW10: =MAX(0,MIN(100,AW9-IF(AV10<Params!$B$44,(Params!$B$44-AV10)*Params!$B$45,0)-IF(AJ10<0,Params!$B$54,0)-IF(AU10="BREACH",Params!$B$53,0)-IF(T10="DARK",Params!$B$55,0))) | AX10: =IF(AW10<=0,"DEAD",TRIM(IF(V10<0,"OVERWORK ","")&IF(W10<0,"NO-DAYLIGHT ","")&IF(AG10<0,"NO-LOGS ","")&IF(AH10<0,"NO-BOARDS ","")&IF(AI10<0,"NO-FUEL ","")&IF(AJ10<0,"HUNGER ","")&AU10&" "&IF(T10="DARK","DARK-TRIP ","")&IF(AV10<Params!$B$44,"COLD","")))
A11: 3 | B11: =IF(A11<=Params!$B$5,"prep","night") | C11: =MAX(0,A11-Params!$B$5) | D11: =IF(A11<=Params!$B$5,ROUND(Params!$B$7-(Params!$B$7-Params!$B$8)*(A11-1)/(Params!$B$5-1),1),0) | E11: =COUNTIFS(People!$F$2:$F$7,"<="&A11,People!$F$2:$F$7,">0") | F11: =IF(E11=0,1,SUMIFS(People!$C$2:$C$7,People!$F$2:$F$7,"<="&A11,People!$F$2:$F$7,">0")/E11) | G11: =E11*Params!$B$9 | H11: 5.4 | I11: 5 | J11: 2 | K11: 0 | L11: 0 | M11: 1 | N11: SHOP | O11: A | P11: R03 | Q11: B | R11: =IF(N11="",0,(2*INDEX(Houses!$D$2:$D$18,MATCH(N11,Houses!$A$2:$A$18,0))+Params!$B$57)/IF(O11="",1,INDEX(People!$D$2:$D$7,MATCH(O11,People!$A$2:$A$7,0)))) | S11: =IF(P11="",0,(2*INDEX(Houses!$D$2:$D$18,MATCH(P11,Houses!$A$2:$A$18,0))+Params!$B$57)/IF(Q11="",1,INDEX(People!$D$2:$D$7,MATCH(Q11,People!$A$2:$A$7,0)))) | T11: =IF(AND(N11="",P11=""),"",IF(MAX(R11,S11)<=D11,"ok","DARK")) | U11: =H11+I11+J11+K11*Params!$B$32+L11*Params!$B$34+M11*Params!$B$37+R11+S11 | V11: =G11-U11 | W11: =D11*E11-(H11+R11+S11) | X11: 1 | Y11: =IF(N11="",0,IF(O11="",8,INDEX(People!$E$2:$E$7,MATCH(O11,People!$A$2:$A$7,0)))) | Z11: =IF(N11="",0,MAX(0,MIN(INDEX(Houses!$E$2:$E$18,MATCH(N11,Houses!$A$2:$A$18,0))-IF(INDEX(Houses!$H$2:$H$18,MATCH(N11,Houses!$A$2:$A$18,0))=1,SUMIF($N$8:N10,N11,$Z$8:Z10)+SUMIF($P$8:P10,N11,$AD$8:AD10),0),Y11))) | AA11: =IF(N11="",0,MAX(0,MIN(INDEX(Houses!$F$2:$F$18,MATCH(N11,Houses!$A$2:$A$18,0))-IF(INDEX(Houses!$H$2:$H$18,MATCH(N11,Houses!$A$2:$A$18,0))=1,SUMIF($N$8:N10,N11,$AA$8:AA10)+SUMIF($P$8:P10,N11,$AE$8:AE10),0),INT((Y11-Z11)/2)))) | AB11: =IF(N11="",0,MAX(0,INDEX(Houses!$G$2:$G$18,MATCH(N11,Houses!$A$2:$A$18,0))-IF(INDEX(Houses!$H$2:$H$18,MATCH(N11,Houses!$A$2:$A$18,0))=1,SUMIF($N$8:N10,N11,$AB$8:AB10)+SUMIF($P$8:P10,N11,$AF$8:AF10),0))) | AC11: =IF(P11="",0,IF(Q11="",8,INDEX(People!$E$2:$E$7,MATCH(Q11,People!$A$2:$A$7,0)))) | AD11: =IF(P11="",0,MAX(0,MIN(INDEX(Houses!$E$2:$E$18,MATCH(P11,Houses!$A$2:$A$18,0))-IF(INDEX(Houses!$H$2:$H$18,MATCH(P11,Houses!$A$2:$A$18,0))=1,SUMIF($P$8:P10,P11,$AD$8:AD10)+SUMIF($N$8:N10,P11,$Z$8:Z10)+IF(N11=P11,Z11,0),0),AC11))) | AE11: =IF(P11="",0,MAX(0,MIN(INDEX(Houses!$F$2:$F$18,MATCH(P11,Houses!$A$2:$A$18,0))-IF(INDEX(Houses!$H$2:$H$18,MATCH(P11,Houses!$A$2:$A$18,0))=1,SUMIF($P$8:P10,P11,$AE$8:AE10)+SUMIF($N$8:N10,P11,$AA$8:AA10)+IF(N11=P11,AA11,0),0),INT((AC11-AD11)/2)))) | AF11: =IF(P11="",0,MAX(0,INDEX(Houses!$G$2:$G$18,MATCH(P11,Houses!$A$2:$A$18,0))-IF(INDEX(Houses!$H$2:$H$18,MATCH(P11,Houses!$A$2:$A$18,0))=1,SUMIF($P$8:P10,P11,$AF$8:AF10)+SUMIF($N$8:N10,P11,$AB$8:AB10)+IF(N11=P11,AB11,0),0))) | AG11: =AG10+H11*Params!$B$24*F11-I11*Params!$B$25-J11*Params!$B$27 | AH11: =AH10+I11*Params!$B$25*Params!$B$26-K11*Params!$B$31-L11*Params!$B$33-M11*Params!$B$36+AA11+AE11 | AI11: =AI10+J11*Params!$B$27*Params!$B$28-X11*Params!$B$43*24 | AJ11: =AJ10-E11*Params!$B$22+Z11+AD11 | AK11: =AK10+AB11+AF11 | AL11: =MAX(0,AL10-M11) | AM11: =MAX(0,AT10-K11) | AN11: =AQ10+L11*Params!$B$35 | AO11: =IF(C11=0,0,INDEX(Nights!$B$2:$B$31,C11)) | AP11: =AO11*Params!$B$51*Params!$B$50 | AQ11: =MAX(0,AN11-AP11) | AR11: =INT((AS10+MAX(0,AP11-AN11))/Params!$B$30) | AS11: =(AS10+MAX(0,AP11-AN11))-AR11*Params!$B$30 | AT11: =AM11+AR11 | AU11: =IF(AND(AO11>0,OR(AM11+AL11>0,AR11>0)),"BREACH","") | AV11: =Params!$B$40+IF(AI11<0,0,X11)*Params!$B$41-(AM11+AL11)*Params!$B$42 | AW11: =MAX(0,MIN(100,AW10-IF(AV11<Params!$B$44,(Params!$B$44-AV11)*Params!$B$45,0)-IF(AJ11<0,Params!$B$54,0)-IF(AU11="BREACH",Params!$B$53,0)-IF(T11="DARK",Params!$B$55,0))) | AX11: =IF(AW11<=0,"DEAD",TRIM(IF(V11<0,"OVERWORK ","")&IF(W11<0,"NO-DAYLIGHT ","")&IF(AG11<0,"NO-LOGS ","")&IF(AH11<0,"NO-BOARDS ","")&IF(AI11<0,"NO-FUEL ","")&IF(AJ11<0,"HUNGER ","")&AU11&" "&IF(T11="DARK","DARK-TRIP ","")&IF(AV11<Params!$B$44,"COLD","")))
A12: 4 | B12: =IF(A12<=Params!$B$5,"prep","night") | C12: =MAX(0,A12-Params!$B$5) | D12: =IF(A12<=Params!$B$5,ROUND(Params!$B$7-(Params!$B$7-Params!$B$8)*(A12-1)/(Params!$B$5-1),1),0) | E12: =COUNTIFS(People!$F$2:$F$7,"<="&A12,People!$F$2:$F$7,">0") | F12: =IF(E12=0,1,SUMIFS(People!$C$2:$C$7,People!$F$2:$F$7,"<="&A12,People!$F$2:$F$7,">0")/E12) | G12: =E12*Params!$B$9 | H12: 4.4 | I12: 7 | J12: 1 | K12: 0 | L12: 0 | M12: 1 | N12: SHOP | O12: A | P12: R06 | Q12: B | R12: =IF(N12="",0,(2*INDEX(Houses!$D$2:$D$18,MATCH(N12,Houses!$A$2:$A$18,0))+Params!$B$57)/IF(O12="",1,INDEX(People!$D$2:$D$7,MATCH(O12,People!$A$2:$A$7,0)))) | S12: =IF(P12="",0,(2*INDEX(Houses!$D$2:$D$18,MATCH(P12,Houses!$A$2:$A$18,0))+Params!$B$57)/IF(Q12="",1,INDEX(People!$D$2:$D$7,MATCH(Q12,People!$A$2:$A$7,0)))) | T12: =IF(AND(N12="",P12=""),"",IF(MAX(R12,S12)<=D12,"ok","DARK")) | U12: =H12+I12+J12+K12*Params!$B$32+L12*Params!$B$34+M12*Params!$B$37+R12+S12 | V12: =G12-U12 | W12: =D12*E12-(H12+R12+S12) | X12: 1 | Y12: =IF(N12="",0,IF(O12="",8,INDEX(People!$E$2:$E$7,MATCH(O12,People!$A$2:$A$7,0)))) | Z12: =IF(N12="",0,MAX(0,MIN(INDEX(Houses!$E$2:$E$18,MATCH(N12,Houses!$A$2:$A$18,0))-IF(INDEX(Houses!$H$2:$H$18,MATCH(N12,Houses!$A$2:$A$18,0))=1,SUMIF($N$8:N11,N12,$Z$8:Z11)+SUMIF($P$8:P11,N12,$AD$8:AD11),0),Y12))) | AA12: =IF(N12="",0,MAX(0,MIN(INDEX(Houses!$F$2:$F$18,MATCH(N12,Houses!$A$2:$A$18,0))-IF(INDEX(Houses!$H$2:$H$18,MATCH(N12,Houses!$A$2:$A$18,0))=1,SUMIF($N$8:N11,N12,$AA$8:AA11)+SUMIF($P$8:P11,N12,$AE$8:AE11),0),INT((Y12-Z12)/2)))) | AB12: =IF(N12="",0,MAX(0,INDEX(Houses!$G$2:$G$18,MATCH(N12,Houses!$A$2:$A$18,0))-IF(INDEX(Houses!$H$2:$H$18,MATCH(N12,Houses!$A$2:$A$18,0))=1,SUMIF($N$8:N11,N12,$AB$8:AB11)+SUMIF($P$8:P11,N12,$AF$8:AF11),0))) | AC12: =IF(P12="",0,IF(Q12="",8,INDEX(People!$E$2:$E$7,MATCH(Q12,People!$A$2:$A$7,0)))) | AD12: =IF(P12="",0,MAX(0,MIN(INDEX(Houses!$E$2:$E$18,MATCH(P12,Houses!$A$2:$A$18,0))-IF(INDEX(Houses!$H$2:$H$18,MATCH(P12,Houses!$A$2:$A$18,0))=1,SUMIF($P$8:P11,P12,$AD$8:AD11)+SUMIF($N$8:N11,P12,$Z$8:Z11)+IF(N12=P12,Z12,0),0),AC12))) | AE12: =IF(P12="",0,MAX(0,MIN(INDEX(Houses!$F$2:$F$18,MATCH(P12,Houses!$A$2:$A$18,0))-IF(INDEX(Houses!$H$2:$H$18,MATCH(P12,Houses!$A$2:$A$18,0))=1,SUMIF($P$8:P11,P12,$AE$8:AE11)+SUMIF($N$8:N11,P12,$AA$8:AA11)+IF(N12=P12,AA12,0),0),INT((AC12-AD12)/2)))) | AF12: =IF(P12="",0,MAX(0,INDEX(Houses!$G$2:$G$18,MATCH(P12,Houses!$A$2:$A$18,0))-IF(INDEX(Houses!$H$2:$H$18,MATCH(P12,Houses!$A$2:$A$18,0))=1,SUMIF($P$8:P11,P12,$AF$8:AF11)+SUMIF($N$8:N11,P12,$AB$8:AB11)+IF(N12=P12,AB12,0),0))) | AG12: =AG11+H12*Params!$B$24*F12-I12*Params!$B$25-J12*Params!$B$27 | AH12: =AH11+I12*Params!$B$25*Params!$B$26-K12*Params!$B$31-L12*Params!$B$33-M12*Params!$B$36+AA12+AE12 | AI12: =AI11+J12*Params!$B$27*Params!$B$28-X12*Params!$B$43*24 | AJ12: =AJ11-E12*Params!$B$22+Z12+AD12 | AK12: =AK11+AB12+AF12 | AL12: =MAX(0,AL11-M12) | AM12: =MAX(0,AT11-K12) | AN12: =AQ11+L12*Params!$B$35 | AO12: =IF(C12=0,0,INDEX(Nights!$B$2:$B$31,C12)) | AP12: =AO12*Params!$B$51*Params!$B$50 | AQ12: =MAX(0,AN12-AP12) | AR12: =INT((AS11+MAX(0,AP12-AN12))/Params!$B$30) | AS12: =(AS11+MAX(0,AP12-AN12))-AR12*Params!$B$30 | AT12: =AM12+AR12 | AU12: =IF(AND(AO12>0,OR(AM12+AL12>0,AR12>0)),"BREACH","") | AV12: =Params!$B$40+IF(AI12<0,0,X12)*Params!$B$41-(AM12+AL12)*Params!$B$42 | AW12: =MAX(0,MIN(100,AW11-IF(AV12<Params!$B$44,(Params!$B$44-AV12)*Params!$B$45,0)-IF(AJ12<0,Params!$B$54,0)-IF(AU12="BREACH",Params!$B$53,0)-IF(T12="DARK",Params!$B$55,0))) | AX12: =IF(AW12<=0,"DEAD",TRIM(IF(V12<0,"OVERWORK ","")&IF(W12<0,"NO-DAYLIGHT ","")&IF(AG12<0,"NO-LOGS ","")&IF(AH12<0,"NO-BOARDS ","")&IF(AI12<0,"NO-FUEL ","")&IF(AJ12<0,"HUNGER ","")&AU12&" "&IF(T12="DARK","DARK-TRIP ","")&IF(AV12<Params!$B$44,"COLD","")))
A13: 5 | B13: =IF(A13<=Params!$B$5,"prep","night") | C13: =MAX(0,A13-Params!$B$5) | D13: =IF(A13<=Params!$B$5,ROUND(Params!$B$7-(Params!$B$7-Params!$B$8)*(A13-1)/(Params!$B$5-1),1),0) | E13: =COUNTIFS(People!$F$2:$F$7,"<="&A13,People!$F$2:$F$7,">0") | F13: =IF(E13=0,1,SUMIFS(People!$C$2:$C$7,People!$F$2:$F$7,"<="&A13,People!$F$2:$F$7,">0")/E13) | G13: =E13*Params!$B$9 | H13: 9.2 | I13: 8 | J13: 1 | K13: 0 | L13: 0 | M13: 1 | N13: R05 | O13: B | R13: =IF(N13="",0,(2*INDEX(Houses!$D$2:$D$18,MATCH(N13,Houses!$A$2:$A$18,0))+Params!$B$57)/IF(O13="",1,INDEX(People!$D$2:$D$7,MATCH(O13,People!$A$2:$A$7,0)))) | S13: =IF(P13="",0,(2*INDEX(Houses!$D$2:$D$18,MATCH(P13,Houses!$A$2:$A$18,0))+Params!$B$57)/IF(Q13="",1,INDEX(People!$D$2:$D$7,MATCH(Q13,People!$A$2:$A$7,0)))) | T13: =IF(AND(N13="",P13=""),"",IF(MAX(R13,S13)<=D13,"ok","DARK")) | U13: =H13+I13+J13+K13*Params!$B$32+L13*Params!$B$34+M13*Params!$B$37+R13+S13 | V13: =G13-U13 | W13: =D13*E13-(H13+R13+S13) | X13: 1 | Y13: =IF(N13="",0,IF(O13="",8,INDEX(People!$E$2:$E$7,MATCH(O13,People!$A$2:$A$7,0)))) | Z13: =IF(N13="",0,MAX(0,MIN(INDEX(Houses!$E$2:$E$18,MATCH(N13,Houses!$A$2:$A$18,0))-IF(INDEX(Houses!$H$2:$H$18,MATCH(N13,Houses!$A$2:$A$18,0))=1,SUMIF($N$8:N12,N13,$Z$8:Z12)+SUMIF($P$8:P12,N13,$AD$8:AD12),0),Y13))) | AA13: =IF(N13="",0,MAX(0,MIN(INDEX(Houses!$F$2:$F$18,MATCH(N13,Houses!$A$2:$A$18,0))-IF(INDEX(Houses!$H$2:$H$18,MATCH(N13,Houses!$A$2:$A$18,0))=1,SUMIF($N$8:N12,N13,$AA$8:AA12)+SUMIF($P$8:P12,N13,$AE$8:AE12),0),INT((Y13-Z13)/2)))) | AB13: =IF(N13="",0,MAX(0,INDEX(Houses!$G$2:$G$18,MATCH(N13,Houses!$A$2:$A$18,0))-IF(INDEX(Houses!$H$2:$H$18,MATCH(N13,Houses!$A$2:$A$18,0))=1,SUMIF($N$8:N12,N13,$AB$8:AB12)+SUMIF($P$8:P12,N13,$AF$8:AF12),0))) | AC13: =IF(P13="",0,IF(Q13="",8,INDEX(People!$E$2:$E$7,MATCH(Q13,People!$A$2:$A$7,0)))) | AD13: =IF(P13="",0,MAX(0,MIN(INDEX(Houses!$E$2:$E$18,MATCH(P13,Houses!$A$2:$A$18,0))-IF(INDEX(Houses!$H$2:$H$18,MATCH(P13,Houses!$A$2:$A$18,0))=1,SUMIF($P$8:P12,P13,$AD$8:AD12)+SUMIF($N$8:N12,P13,$Z$8:Z12)+IF(N13=P13,Z13,0),0),AC13))) | AE13: =IF(P13="",0,MAX(0,MIN(INDEX(Houses!$F$2:$F$18,MATCH(P13,Houses!$A$2:$A$18,0))-IF(INDEX(Houses!$H$2:$H$18,MATCH(P13,Houses!$A$2:$A$18,0))=1,SUMIF($P$8:P12,P13,$AE$8:AE12)+SUMIF($N$8:N12,P13,$AA$8:AA12)+IF(N13=P13,AA13,0),0),INT((AC13-AD13)/2)))) | AF13: =IF(P13="",0,MAX(0,INDEX(Houses!$G$2:$G$18,MATCH(P13,Houses!$A$2:$A$18,0))-IF(INDEX(Houses!$H$2:$H$18,MATCH(P13,Houses!$A$2:$A$18,0))=1,SUMIF($P$8:P12,P13,$AF$8:AF12)+SUMIF($N$8:N12,P13,$AB$8:AB12)+IF(N13=P13,AB13,0),0))) | AG13: =AG12+H13*Params!$B$24*F13-I13*Params!$B$25-J13*Params!$B$27 | AH13: =AH12+I13*Params!$B$25*Params!$B$26-K13*Params!$B$31-L13*Params!$B$33-M13*Params!$B$36+AA13+AE13 | AI13: =AI12+J13*Params!$B$27*Params!$B$28-X13*Params!$B$43*24 | AJ13: =AJ12-E13*Params!$B$22+Z13+AD13 | AK13: =AK12+AB13+AF13 | AL13: =MAX(0,AL12-M13) | AM13: =MAX(0,AT12-K13) | AN13: =AQ12+L13*Params!$B$35 | AO13: =IF(C13=0,0,INDEX(Nights!$B$2:$B$31,C13)) | AP13: =AO13*Params!$B$51*Params!$B$50 | AQ13: =MAX(0,AN13-AP13) | AR13: =INT((AS12+MAX(0,AP13-AN13))/Params!$B$30) | AS13: =(AS12+MAX(0,AP13-AN13))-AR13*Params!$B$30 | AT13: =AM13+AR13 | AU13: =IF(AND(AO13>0,OR(AM13+AL13>0,AR13>0)),"BREACH","") | AV13: =Params!$B$40+IF(AI13<0,0,X13)*Params!$B$41-(AM13+AL13)*Params!$B$42 | AW13: =MAX(0,MIN(100,AW12-IF(AV13<Params!$B$44,(Params!$B$44-AV13)*Params!$B$45,0)-IF(AJ13<0,Params!$B$54,0)-IF(AU13="BREACH",Params!$B$53,0)-IF(T13="DARK",Params!$B$55,0))) | AX13: =IF(AW13<=0,"DEAD",TRIM(IF(V13<0,"OVERWORK ","")&IF(W13<0,"NO-DAYLIGHT ","")&IF(AG13<0,"NO-LOGS ","")&IF(AH13<0,"NO-BOARDS ","")&IF(AI13<0,"NO-FUEL ","")&IF(AJ13<0,"HUNGER ","")&AU13&" "&IF(T13="DARK","DARK-TRIP ","")&IF(AV13<Params!$B$44,"COLD","")))
A14: 6 | B14: =IF(A14<=Params!$B$5,"prep","night") | C14: =MAX(0,A14-Params!$B$5) | D14: =IF(A14<=Params!$B$5,ROUND(Params!$B$7-(Params!$B$7-Params!$B$8)*(A14-1)/(Params!$B$5-1),1),0) | E14: =COUNTIFS(People!$F$2:$F$7,"<="&A14,People!$F$2:$F$7,">0") | F14: =IF(E14=0,1,SUMIFS(People!$C$2:$C$7,People!$F$2:$F$7,"<="&A14,People!$F$2:$F$7,">0")/E14) | G14: =E14*Params!$B$9 | H14: 8.2 | I14: 1 | J14: 7 | K14: 0 | L14: 0 | M14: 0 | N14: R04 | O14: B | R14: =IF(N14="",0,(2*INDEX(Houses!$D$2:$D$18,MATCH(N14,Houses!$A$2:$A$18,0))+Params!$B$57)/IF(O14="",1,INDEX(People!$D$2:$D$7,MATCH(O14,People!$A$2:$A$7,0)))) | S14: =IF(P14="",0,(2*INDEX(Houses!$D$2:$D$18,MATCH(P14,Houses!$A$2:$A$18,0))+Params!$B$57)/IF(Q14="",1,INDEX(People!$D$2:$D$7,MATCH(Q14,People!$A$2:$A$7,0)))) | T14: =IF(AND(N14="",P14=""),"",IF(MAX(R14,S14)<=D14,"ok","DARK")) | U14: =H14+I14+J14+K14*Params!$B$32+L14*Params!$B$34+M14*Params!$B$37+R14+S14 | V14: =G14-U14 | W14: =D14*E14-(H14+R14+S14) | X14: 1 | Y14: =IF(N14="",0,IF(O14="",8,INDEX(People!$E$2:$E$7,MATCH(O14,People!$A$2:$A$7,0)))) | Z14: =IF(N14="",0,MAX(0,MIN(INDEX(Houses!$E$2:$E$18,MATCH(N14,Houses!$A$2:$A$18,0))-IF(INDEX(Houses!$H$2:$H$18,MATCH(N14,Houses!$A$2:$A$18,0))=1,SUMIF($N$8:N13,N14,$Z$8:Z13)+SUMIF($P$8:P13,N14,$AD$8:AD13),0),Y14))) | AA14: =IF(N14="",0,MAX(0,MIN(INDEX(Houses!$F$2:$F$18,MATCH(N14,Houses!$A$2:$A$18,0))-IF(INDEX(Houses!$H$2:$H$18,MATCH(N14,Houses!$A$2:$A$18,0))=1,SUMIF($N$8:N13,N14,$AA$8:AA13)+SUMIF($P$8:P13,N14,$AE$8:AE13),0),INT((Y14-Z14)/2)))) | AB14: =IF(N14="",0,MAX(0,INDEX(Houses!$G$2:$G$18,MATCH(N14,Houses!$A$2:$A$18,0))-IF(INDEX(Houses!$H$2:$H$18,MATCH(N14,Houses!$A$2:$A$18,0))=1,SUMIF($N$8:N13,N14,$AB$8:AB13)+SUMIF($P$8:P13,N14,$AF$8:AF13),0))) | AC14: =IF(P14="",0,IF(Q14="",8,INDEX(People!$E$2:$E$7,MATCH(Q14,People!$A$2:$A$7,0)))) | AD14: =IF(P14="",0,MAX(0,MIN(INDEX(Houses!$E$2:$E$18,MATCH(P14,Houses!$A$2:$A$18,0))-IF(INDEX(Houses!$H$2:$H$18,MATCH(P14,Houses!$A$2:$A$18,0))=1,SUMIF($P$8:P13,P14,$AD$8:AD13)+SUMIF($N$8:N13,P14,$Z$8:Z13)+IF(N14=P14,Z14,0),0),AC14))) | AE14: =IF(P14="",0,MAX(0,MIN(INDEX(Houses!$F$2:$F$18,MATCH(P14,Houses!$A$2:$A$18,0))-IF(INDEX(Houses!$H$2:$H$18,MATCH(P14,Houses!$A$2:$A$18,0))=1,SUMIF($P$8:P13,P14,$AE$8:AE13)+SUMIF($N$8:N13,P14,$AA$8:AA13)+IF(N14=P14,AA14,0),0),INT((AC14-AD14)/2)))) | AF14: =IF(P14="",0,MAX(0,INDEX(Houses!$G$2:$G$18,MATCH(P14,Houses!$A$2:$A$18,0))-IF(INDEX(Houses!$H$2:$H$18,MATCH(P14,Houses!$A$2:$A$18,0))=1,SUMIF($P$8:P13,P14,$AF$8:AF13)+SUMIF($N$8:N13,P14,$AB$8:AB13)+IF(N14=P14,AB14,0),0))) | AG14: =AG13+H14*Params!$B$24*F14-I14*Params!$B$25-J14*Params!$B$27 | AH14: =AH13+I14*Params!$B$25*Params!$B$26-K14*Params!$B$31-L14*Params!$B$33-M14*Params!$B$36+AA14+AE14 | AI14: =AI13+J14*Params!$B$27*Params!$B$28-X14*Params!$B$43*24 | AJ14: =AJ13-E14*Params!$B$22+Z14+AD14 | AK14: =AK13+AB14+AF14 | AL14: =MAX(0,AL13-M14) | AM14: =MAX(0,AT13-K14) | AN14: =AQ13+L14*Params!$B$35 | AO14: =IF(C14=0,0,INDEX(Nights!$B$2:$B$31,C14)) | AP14: =AO14*Params!$B$51*Params!$B$50 | AQ14: =MAX(0,AN14-AP14) | AR14: =INT((AS13+MAX(0,AP14-AN14))/Params!$B$30) | AS14: =(AS13+MAX(0,AP14-AN14))-AR14*Params!$B$30 | AT14: =AM14+AR14 | AU14: =IF(AND(AO14>0,OR(AM14+AL14>0,AR14>0)),"BREACH","") | AV14: =Params!$B$40+IF(AI14<0,0,X14)*Params!$B$41-(AM14+AL14)*Params!$B$42 | AW14: =MAX(0,MIN(100,AW13-IF(AV14<Params!$B$44,(Params!$B$44-AV14)*Params!$B$45,0)-IF(AJ14<0,Params!$B$54,0)-IF(AU14="BREACH",Params!$B$53,0)-IF(T14="DARK",Params!$B$55,0))) | AX14: =IF(AW14<=0,"DEAD",TRIM(IF(V14<0,"OVERWORK ","")&IF(W14<0,"NO-DAYLIGHT ","")&IF(AG14<0,"NO-LOGS ","")&IF(AH14<0,"NO-BOARDS ","")&IF(AI14<0,"NO-FUEL ","")&IF(AJ14<0,"HUNGER ","")&AU14&" "&IF(T14="DARK","DARK-TRIP ","")&IF(AV14<Params!$B$44,"COLD","")))
A15: 7 | B15: =IF(A15<=Params!$B$5,"prep","night") | C15: =MAX(0,A15-Params!$B$5) | D15: =IF(A15<=Params!$B$5,ROUND(Params!$B$7-(Params!$B$7-Params!$B$8)*(A15-1)/(Params!$B$5-1),1),0) | E15: =COUNTIFS(People!$F$2:$F$7,"<="&A15,People!$F$2:$F$7,">0") | F15: =IF(E15=0,1,SUMIFS(People!$C$2:$C$7,People!$F$2:$F$7,"<="&A15,People!$F$2:$F$7,">0")/E15) | G15: =E15*Params!$B$9 | H15: 9.6 | I15: 0 | J15: 1 | K15: 0 | L15: 0 | M15: 0 | R15: =IF(N15="",0,(2*INDEX(Houses!$D$2:$D$18,MATCH(N15,Houses!$A$2:$A$18,0))+Params!$B$57)/IF(O15="",1,INDEX(People!$D$2:$D$7,MATCH(O15,People!$A$2:$A$7,0)))) | S15: =IF(P15="",0,(2*INDEX(Houses!$D$2:$D$18,MATCH(P15,Houses!$A$2:$A$18,0))+Params!$B$57)/IF(Q15="",1,INDEX(People!$D$2:$D$7,MATCH(Q15,People!$A$2:$A$7,0)))) | T15: =IF(AND(N15="",P15=""),"",IF(MAX(R15,S15)<=D15,"ok","DARK")) | U15: =H15+I15+J15+K15*Params!$B$32+L15*Params!$B$34+M15*Params!$B$37+R15+S15 | V15: =G15-U15 | W15: =D15*E15-(H15+R15+S15) | X15: 1 | Y15: =IF(N15="",0,IF(O15="",8,INDEX(People!$E$2:$E$7,MATCH(O15,People!$A$2:$A$7,0)))) | Z15: =IF(N15="",0,MAX(0,MIN(INDEX(Houses!$E$2:$E$18,MATCH(N15,Houses!$A$2:$A$18,0))-IF(INDEX(Houses!$H$2:$H$18,MATCH(N15,Houses!$A$2:$A$18,0))=1,SUMIF($N$8:N14,N15,$Z$8:Z14)+SUMIF($P$8:P14,N15,$AD$8:AD14),0),Y15))) | AA15: =IF(N15="",0,MAX(0,MIN(INDEX(Houses!$F$2:$F$18,MATCH(N15,Houses!$A$2:$A$18,0))-IF(INDEX(Houses!$H$2:$H$18,MATCH(N15,Houses!$A$2:$A$18,0))=1,SUMIF($N$8:N14,N15,$AA$8:AA14)+SUMIF($P$8:P14,N15,$AE$8:AE14),0),INT((Y15-Z15)/2)))) | AB15: =IF(N15="",0,MAX(0,INDEX(Houses!$G$2:$G$18,MATCH(N15,Houses!$A$2:$A$18,0))-IF(INDEX(Houses!$H$2:$H$18,MATCH(N15,Houses!$A$2:$A$18,0))=1,SUMIF($N$8:N14,N15,$AB$8:AB14)+SUMIF($P$8:P14,N15,$AF$8:AF14),0))) | AC15: =IF(P15="",0,IF(Q15="",8,INDEX(People!$E$2:$E$7,MATCH(Q15,People!$A$2:$A$7,0)))) | AD15: =IF(P15="",0,MAX(0,MIN(INDEX(Houses!$E$2:$E$18,MATCH(P15,Houses!$A$2:$A$18,0))-IF(INDEX(Houses!$H$2:$H$18,MATCH(P15,Houses!$A$2:$A$18,0))=1,SUMIF($P$8:P14,P15,$AD$8:AD14)+SUMIF($N$8:N14,P15,$Z$8:Z14)+IF(N15=P15,Z15,0),0),AC15))) | AE15: =IF(P15="",0,MAX(0,MIN(INDEX(Houses!$F$2:$F$18,MATCH(P15,Houses!$A$2:$A$18,0))-IF(INDEX(Houses!$H$2:$H$18,MATCH(P15,Houses!$A$2:$A$18,0))=1,SUMIF($P$8:P14,P15,$AE$8:AE14)+SUMIF($N$8:N14,P15,$AA$8:AA14)+IF(N15=P15,AA15,0),0),INT((AC15-AD15)/2)))) | AF15: =IF(P15="",0,MAX(0,INDEX(Houses!$G$2:$G$18,MATCH(P15,Houses!$A$2:$A$18,0))-IF(INDEX(Houses!$H$2:$H$18,MATCH(P15,Houses!$A$2:$A$18,0))=1,SUMIF($P$8:P14,P15,$AF$8:AF14)+SUMIF($N$8:N14,P15,$AB$8:AB14)+IF(N15=P15,AB15,0),0))) | AG15: =AG14+H15*Params!$B$24*F15-I15*Params!$B$25-J15*Params!$B$27 | AH15: =AH14+I15*Params!$B$25*Params!$B$26-K15*Params!$B$31-L15*Params!$B$33-M15*Params!$B$36+AA15+AE15 | AI15: =AI14+J15*Params!$B$27*Params!$B$28-X15*Params!$B$43*24 | AJ15: =AJ14-E15*Params!$B$22+Z15+AD15 | AK15: =AK14+AB15+AF15 | AL15: =MAX(0,AL14-M15) | AM15: =MAX(0,AT14-K15) | AN15: =AQ14+L15*Params!$B$35 | AO15: =IF(C15=0,0,INDEX(Nights!$B$2:$B$31,C15)) | AP15: =AO15*Params!$B$51*Params!$B$50 | AQ15: =MAX(0,AN15-AP15) | AR15: =INT((AS14+MAX(0,AP15-AN15))/Params!$B$30) | AS15: =(AS14+MAX(0,AP15-AN15))-AR15*Params!$B$30 | AT15: =AM15+AR15 | AU15: =IF(AND(AO15>0,OR(AM15+AL15>0,AR15>0)),"BREACH","") | AV15: =Params!$B$40+IF(AI15<0,0,X15)*Params!$B$41-(AM15+AL15)*Params!$B$42 | AW15: =MAX(0,MIN(100,AW14-IF(AV15<Params!$B$44,(Params!$B$44-AV15)*Params!$B$45,0)-IF(AJ15<0,Params!$B$54,0)-IF(AU15="BREACH",Params!$B$53,0)-IF(T15="DARK",Params!$B$55,0))) | AX15: =IF(AW15<=0,"DEAD",TRIM(IF(V15<0,"OVERWORK ","")&IF(W15<0,"NO-DAYLIGHT ","")&IF(AG15<0,"NO-LOGS ","")&IF(AH15<0,"NO-BOARDS ","")&IF(AI15<0,"NO-FUEL ","")&IF(AJ15<0,"HUNGER ","")&AU15&" "&IF(T15="DARK","DARK-TRIP ","")&IF(AV15<Params!$B$44,"COLD","")))
A16: 8 | B16: =IF(A16<=Params!$B$5,"prep","night") | C16: =MAX(0,A16-Params!$B$5) | D16: =IF(A16<=Params!$B$5,ROUND(Params!$B$7-(Params!$B$7-Params!$B$8)*(A16-1)/(Params!$B$5-1),1),0) | E16: =COUNTIFS(People!$F$2:$F$7,"<="&A16,People!$F$2:$F$7,">0") | F16: =IF(E16=0,1,SUMIFS(People!$C$2:$C$7,People!$F$2:$F$7,"<="&A16,People!$F$2:$F$7,">0")/E16) | G16: =E16*Params!$B$9 | H16: 6.8 | I16: 0 | J16: 2 | K16: 0 | L16: 0 | M16: 0 | N16: R01 | O16: B | R16: =IF(N16="",0,(2*INDEX(Houses!$D$2:$D$18,MATCH(N16,Houses!$A$2:$A$18,0))+Params!$B$57)/IF(O16="",1,INDEX(People!$D$2:$D$7,MATCH(O16,People!$A$2:$A$7,0)))) | S16: =IF(P16="",0,(2*INDEX(Houses!$D$2:$D$18,MATCH(P16,Houses!$A$2:$A$18,0))+Params!$B$57)/IF(Q16="",1,INDEX(People!$D$2:$D$7,MATCH(Q16,People!$A$2:$A$7,0)))) | T16: =IF(AND(N16="",P16=""),"",IF(MAX(R16,S16)<=D16,"ok","DARK")) | U16: =H16+I16+J16+K16*Params!$B$32+L16*Params!$B$34+M16*Params!$B$37+R16+S16 | V16: =G16-U16 | W16: =D16*E16-(H16+R16+S16) | X16: 1 | Y16: =IF(N16="",0,IF(O16="",8,INDEX(People!$E$2:$E$7,MATCH(O16,People!$A$2:$A$7,0)))) | Z16: =IF(N16="",0,MAX(0,MIN(INDEX(Houses!$E$2:$E$18,MATCH(N16,Houses!$A$2:$A$18,0))-IF(INDEX(Houses!$H$2:$H$18,MATCH(N16,Houses!$A$2:$A$18,0))=1,SUMIF($N$8:N15,N16,$Z$8:Z15)+SUMIF($P$8:P15,N16,$AD$8:AD15),0),Y16))) | AA16: =IF(N16="",0,MAX(0,MIN(INDEX(Houses!$F$2:$F$18,MATCH(N16,Houses!$A$2:$A$18,0))-IF(INDEX(Houses!$H$2:$H$18,MATCH(N16,Houses!$A$2:$A$18,0))=1,SUMIF($N$8:N15,N16,$AA$8:AA15)+SUMIF($P$8:P15,N16,$AE$8:AE15),0),INT((Y16-Z16)/2)))) | AB16: =IF(N16="",0,MAX(0,INDEX(Houses!$G$2:$G$18,MATCH(N16,Houses!$A$2:$A$18,0))-IF(INDEX(Houses!$H$2:$H$18,MATCH(N16,Houses!$A$2:$A$18,0))=1,SUMIF($N$8:N15,N16,$AB$8:AB15)+SUMIF($P$8:P15,N16,$AF$8:AF15),0))) | AC16: =IF(P16="",0,IF(Q16="",8,INDEX(People!$E$2:$E$7,MATCH(Q16,People!$A$2:$A$7,0)))) | AD16: =IF(P16="",0,MAX(0,MIN(INDEX(Houses!$E$2:$E$18,MATCH(P16,Houses!$A$2:$A$18,0))-IF(INDEX(Houses!$H$2:$H$18,MATCH(P16,Houses!$A$2:$A$18,0))=1,SUMIF($P$8:P15,P16,$AD$8:AD15)+SUMIF($N$8:N15,P16,$Z$8:Z15)+IF(N16=P16,Z16,0),0),AC16))) | AE16: =IF(P16="",0,MAX(0,MIN(INDEX(Houses!$F$2:$F$18,MATCH(P16,Houses!$A$2:$A$18,0))-IF(INDEX(Houses!$H$2:$H$18,MATCH(P16,Houses!$A$2:$A$18,0))=1,SUMIF($P$8:P15,P16,$AE$8:AE15)+SUMIF($N$8:N15,P16,$AA$8:AA15)+IF(N16=P16,AA16,0),0),INT((AC16-AD16)/2)))) | AF16: =IF(P16="",0,MAX(0,INDEX(Houses!$G$2:$G$18,MATCH(P16,Houses!$A$2:$A$18,0))-IF(INDEX(Houses!$H$2:$H$18,MATCH(P16,Houses!$A$2:$A$18,0))=1,SUMIF($P$8:P15,P16,$AF$8:AF15)+SUMIF($N$8:N15,P16,$AB$8:AB15)+IF(N16=P16,AB16,0),0))) | AG16: =AG15+H16*Params!$B$24*F16-I16*Params!$B$25-J16*Params!$B$27 | AH16: =AH15+I16*Params!$B$25*Params!$B$26-K16*Params!$B$31-L16*Params!$B$33-M16*Params!$B$36+AA16+AE16 | AI16: =AI15+J16*Params!$B$27*Params!$B$28-X16*Params!$B$43*24 | AJ16: =AJ15-E16*Params!$B$22+Z16+AD16 | AK16: =AK15+AB16+AF16 | AL16: =MAX(0,AL15-M16) | AM16: =MAX(0,AT15-K16) | AN16: =AQ15+L16*Params!$B$35 | AO16: =IF(C16=0,0,INDEX(Nights!$B$2:$B$31,C16)) | AP16: =AO16*Params!$B$51*Params!$B$50 | AQ16: =MAX(0,AN16-AP16) | AR16: =INT((AS15+MAX(0,AP16-AN16))/Params!$B$30) | AS16: =(AS15+MAX(0,AP16-AN16))-AR16*Params!$B$30 | AT16: =AM16+AR16 | AU16: =IF(AND(AO16>0,OR(AM16+AL16>0,AR16>0)),"BREACH","") | AV16: =Params!$B$40+IF(AI16<0,0,X16)*Params!$B$41-(AM16+AL16)*Params!$B$42 | AW16: =MAX(0,MIN(100,AW15-IF(AV16<Params!$B$44,(Params!$B$44-AV16)*Params!$B$45,0)-IF(AJ16<0,Params!$B$54,0)-IF(AU16="BREACH",Params!$B$53,0)-IF(T16="DARK",Params!$B$55,0))) | AX16: =IF(AW16<=0,"DEAD",TRIM(IF(V16<0,"OVERWORK ","")&IF(W16<0,"NO-DAYLIGHT ","")&IF(AG16<0,"NO-LOGS ","")&IF(AH16<0,"NO-BOARDS ","")&IF(AI16<0,"NO-FUEL ","")&IF(AJ16<0,"HUNGER ","")&AU16&" "&IF(T16="DARK","DARK-TRIP ","")&IF(AV16<Params!$B$44,"COLD","")))
A17: 9 | B17: =IF(A17<=Params!$B$5,"prep","night") | C17: =MAX(0,A17-Params!$B$5) | D17: =IF(A17<=Params!$B$5,ROUND(Params!$B$7-(Params!$B$7-Params!$B$8)*(A17-1)/(Params!$B$5-1),1),0) | E17: =COUNTIFS(People!$F$2:$F$7,"<="&A17,People!$F$2:$F$7,">0") | F17: =IF(E17=0,1,SUMIFS(People!$C$2:$C$7,People!$F$2:$F$7,"<="&A17,People!$F$2:$F$7,">0")/E17) | G17: =E17*Params!$B$9 | H17: 7.4 | I17: 0 | J17: 1 | K17: 0 | L17: 0 | M17: 0 | R17: =IF(N17="",0,(2*INDEX(Houses!$D$2:$D$18,MATCH(N17,Houses!$A$2:$A$18,0))+Params!$B$57)/IF(O17="",1,INDEX(People!$D$2:$D$7,MATCH(O17,People!$A$2:$A$7,0)))) | S17: =IF(P17="",0,(2*INDEX(Houses!$D$2:$D$18,MATCH(P17,Houses!$A$2:$A$18,0))+Params!$B$57)/IF(Q17="",1,INDEX(People!$D$2:$D$7,MATCH(Q17,People!$A$2:$A$7,0)))) | T17: =IF(AND(N17="",P17=""),"",IF(MAX(R17,S17)<=D17,"ok","DARK")) | U17: =H17+I17+J17+K17*Params!$B$32+L17*Params!$B$34+M17*Params!$B$37+R17+S17 | V17: =G17-U17 | W17: =D17*E17-(H17+R17+S17) | X17: 1 | Y17: =IF(N17="",0,IF(O17="",8,INDEX(People!$E$2:$E$7,MATCH(O17,People!$A$2:$A$7,0)))) | Z17: =IF(N17="",0,MAX(0,MIN(INDEX(Houses!$E$2:$E$18,MATCH(N17,Houses!$A$2:$A$18,0))-IF(INDEX(Houses!$H$2:$H$18,MATCH(N17,Houses!$A$2:$A$18,0))=1,SUMIF($N$8:N16,N17,$Z$8:Z16)+SUMIF($P$8:P16,N17,$AD$8:AD16),0),Y17))) | AA17: =IF(N17="",0,MAX(0,MIN(INDEX(Houses!$F$2:$F$18,MATCH(N17,Houses!$A$2:$A$18,0))-IF(INDEX(Houses!$H$2:$H$18,MATCH(N17,Houses!$A$2:$A$18,0))=1,SUMIF($N$8:N16,N17,$AA$8:AA16)+SUMIF($P$8:P16,N17,$AE$8:AE16),0),INT((Y17-Z17)/2)))) | AB17: =IF(N17="",0,MAX(0,INDEX(Houses!$G$2:$G$18,MATCH(N17,Houses!$A$2:$A$18,0))-IF(INDEX(Houses!$H$2:$H$18,MATCH(N17,Houses!$A$2:$A$18,0))=1,SUMIF($N$8:N16,N17,$AB$8:AB16)+SUMIF($P$8:P16,N17,$AF$8:AF16),0))) | AC17: =IF(P17="",0,IF(Q17="",8,INDEX(People!$E$2:$E$7,MATCH(Q17,People!$A$2:$A$7,0)))) | AD17: =IF(P17="",0,MAX(0,MIN(INDEX(Houses!$E$2:$E$18,MATCH(P17,Houses!$A$2:$A$18,0))-IF(INDEX(Houses!$H$2:$H$18,MATCH(P17,Houses!$A$2:$A$18,0))=1,SUMIF($P$8:P16,P17,$AD$8:AD16)+SUMIF($N$8:N16,P17,$Z$8:Z16)+IF(N17=P17,Z17,0),0),AC17))) | AE17: =IF(P17="",0,MAX(0,MIN(INDEX(Houses!$F$2:$F$18,MATCH(P17,Houses!$A$2:$A$18,0))-IF(INDEX(Houses!$H$2:$H$18,MATCH(P17,Houses!$A$2:$A$18,0))=1,SUMIF($P$8:P16,P17,$AE$8:AE16)+SUMIF($N$8:N16,P17,$AA$8:AA16)+IF(N17=P17,AA17,0),0),INT((AC17-AD17)/2)))) | AF17: =IF(P17="",0,MAX(0,INDEX(Houses!$G$2:$G$18,MATCH(P17,Houses!$A$2:$A$18,0))-IF(INDEX(Houses!$H$2:$H$18,MATCH(P17,Houses!$A$2:$A$18,0))=1,SUMIF($P$8:P16,P17,$AF$8:AF16)+SUMIF($N$8:N16,P17,$AB$8:AB16)+IF(N17=P17,AB17,0),0))) | AG17: =AG16+H17*Params!$B$24*F17-I17*Params!$B$25-J17*Params!$B$27 | AH17: =AH16+I17*Params!$B$25*Params!$B$26-K17*Params!$B$31-L17*Params!$B$33-M17*Params!$B$36+AA17+AE17 | AI17: =AI16+J17*Params!$B$27*Params!$B$28-X17*Params!$B$43*24 | AJ17: =AJ16-E17*Params!$B$22+Z17+AD17 | AK17: =AK16+AB17+AF17 | AL17: =MAX(0,AL16-M17) | AM17: =MAX(0,AT16-K17) | AN17: =AQ16+L17*Params!$B$35 | AO17: =IF(C17=0,0,INDEX(Nights!$B$2:$B$31,C17)) | AP17: =AO17*Params!$B$51*Params!$B$50 | AQ17: =MAX(0,AN17-AP17) | AR17: =INT((AS16+MAX(0,AP17-AN17))/Params!$B$30) | AS17: =(AS16+MAX(0,AP17-AN17))-AR17*Params!$B$30 | AT17: =AM17+AR17 | AU17: =IF(AND(AO17>0,OR(AM17+AL17>0,AR17>0)),"BREACH","") | AV17: =Params!$B$40+IF(AI17<0,0,X17)*Params!$B$41-(AM17+AL17)*Params!$B$42 | AW17: =MAX(0,MIN(100,AW16-IF(AV17<Params!$B$44,(Params!$B$44-AV17)*Params!$B$45,0)-IF(AJ17<0,Params!$B$54,0)-IF(AU17="BREACH",Params!$B$53,0)-IF(T17="DARK",Params!$B$55,0))) | AX17: =IF(AW17<=0,"DEAD",TRIM(IF(V17<0,"OVERWORK ","")&IF(W17<0,"NO-DAYLIGHT ","")&IF(AG17<0,"NO-LOGS ","")&IF(AH17<0,"NO-BOARDS ","")&IF(AI17<0,"NO-FUEL ","")&IF(AJ17<0,"HUNGER ","")&AU17&" "&IF(T17="DARK","DARK-TRIP ","")&IF(AV17<Params!$B$44,"COLD","")))
A18: 10 | B18: =IF(A18<=Params!$B$5,"prep","night") | C18: =MAX(0,A18-Params!$B$5) | D18: =IF(A18<=Params!$B$5,ROUND(Params!$B$7-(Params!$B$7-Params!$B$8)*(A18-1)/(Params!$B$5-1),1),0) | E18: =COUNTIFS(People!$F$2:$F$7,"<="&A18,People!$F$2:$F$7,">0") | F18: =IF(E18=0,1,SUMIFS(People!$C$2:$C$7,People!$F$2:$F$7,"<="&A18,People!$F$2:$F$7,">0")/E18) | G18: =E18*Params!$B$9 | H18: 4.8 | I18: 0 | J18: 1 | K18: 0 | L18: 0 | M18: 0 | N18: R02 | O18: B | R18: =IF(N18="",0,(2*INDEX(Houses!$D$2:$D$18,MATCH(N18,Houses!$A$2:$A$18,0))+Params!$B$57)/IF(O18="",1,INDEX(People!$D$2:$D$7,MATCH(O18,People!$A$2:$A$7,0)))) | S18: =IF(P18="",0,(2*INDEX(Houses!$D$2:$D$18,MATCH(P18,Houses!$A$2:$A$18,0))+Params!$B$57)/IF(Q18="",1,INDEX(People!$D$2:$D$7,MATCH(Q18,People!$A$2:$A$7,0)))) | T18: =IF(AND(N18="",P18=""),"",IF(MAX(R18,S18)<=D18,"ok","DARK")) | U18: =H18+I18+J18+K18*Params!$B$32+L18*Params!$B$34+M18*Params!$B$37+R18+S18 | V18: =G18-U18 | W18: =D18*E18-(H18+R18+S18) | X18: 1 | Y18: =IF(N18="",0,IF(O18="",8,INDEX(People!$E$2:$E$7,MATCH(O18,People!$A$2:$A$7,0)))) | Z18: =IF(N18="",0,MAX(0,MIN(INDEX(Houses!$E$2:$E$18,MATCH(N18,Houses!$A$2:$A$18,0))-IF(INDEX(Houses!$H$2:$H$18,MATCH(N18,Houses!$A$2:$A$18,0))=1,SUMIF($N$8:N17,N18,$Z$8:Z17)+SUMIF($P$8:P17,N18,$AD$8:AD17),0),Y18))) | AA18: =IF(N18="",0,MAX(0,MIN(INDEX(Houses!$F$2:$F$18,MATCH(N18,Houses!$A$2:$A$18,0))-IF(INDEX(Houses!$H$2:$H$18,MATCH(N18,Houses!$A$2:$A$18,0))=1,SUMIF($N$8:N17,N18,$AA$8:AA17)+SUMIF($P$8:P17,N18,$AE$8:AE17),0),INT((Y18-Z18)/2)))) | AB18: =IF(N18="",0,MAX(0,INDEX(Houses!$G$2:$G$18,MATCH(N18,Houses!$A$2:$A$18,0))-IF(INDEX(Houses!$H$2:$H$18,MATCH(N18,Houses!$A$2:$A$18,0))=1,SUMIF($N$8:N17,N18,$AB$8:AB17)+SUMIF($P$8:P17,N18,$AF$8:AF17),0))) | AC18: =IF(P18="",0,IF(Q18="",8,INDEX(People!$E$2:$E$7,MATCH(Q18,People!$A$2:$A$7,0)))) | AD18: =IF(P18="",0,MAX(0,MIN(INDEX(Houses!$E$2:$E$18,MATCH(P18,Houses!$A$2:$A$18,0))-IF(INDEX(Houses!$H$2:$H$18,MATCH(P18,Houses!$A$2:$A$18,0))=1,SUMIF($P$8:P17,P18,$AD$8:AD17)+SUMIF($N$8:N17,P18,$Z$8:Z17)+IF(N18=P18,Z18,0),0),AC18))) | AE18: =IF(P18="",0,MAX(0,MIN(INDEX(Houses!$F$2:$F$18,MATCH(P18,Houses!$A$2:$A$18,0))-IF(INDEX(Houses!$H$2:$H$18,MATCH(P18,Houses!$A$2:$A$18,0))=1,SUMIF($P$8:P17,P18,$AE$8:AE17)+SUMIF($N$8:N17,P18,$AA$8:AA17)+IF(N18=P18,AA18,0),0),INT((AC18-AD18)/2)))) | AF18: =IF(P18="",0,MAX(0,INDEX(Houses!$G$2:$G$18,MATCH(P18,Houses!$A$2:$A$18,0))-IF(INDEX(Houses!$H$2:$H$18,MATCH(P18,Houses!$A$2:$A$18,0))=1,SUMIF($P$8:P17,P18,$AF$8:AF17)+SUMIF($N$8:N17,P18,$AB$8:AB17)+IF(N18=P18,AB18,0),0))) | AG18: =AG17+H18*Params!$B$24*F18-I18*Params!$B$25-J18*Params!$B$27 | AH18: =AH17+I18*Params!$B$25*Params!$B$26-K18*Params!$B$31-L18*Params!$B$33-M18*Params!$B$36+AA18+AE18 | AI18: =AI17+J18*Params!$B$27*Params!$B$28-X18*Params!$B$43*24 | AJ18: =AJ17-E18*Params!$B$22+Z18+AD18 | AK18: =AK17+AB18+AF18 | AL18: =MAX(0,AL17-M18) | AM18: =MAX(0,AT17-K18) | AN18: =AQ17+L18*Params!$B$35 | AO18: =IF(C18=0,0,INDEX(Nights!$B$2:$B$31,C18)) | AP18: =AO18*Params!$B$51*Params!$B$50 | AQ18: =MAX(0,AN18-AP18) | AR18: =INT((AS17+MAX(0,AP18-AN18))/Params!$B$30) | AS18: =(AS17+MAX(0,AP18-AN18))-AR18*Params!$B$30 | AT18: =AM18+AR18 | AU18: =IF(AND(AO18>0,OR(AM18+AL18>0,AR18>0)),"BREACH","") | AV18: =Params!$B$40+IF(AI18<0,0,X18)*Params!$B$41-(AM18+AL18)*Params!$B$42 | AW18: =MAX(0,MIN(100,AW17-IF(AV18<Params!$B$44,(Params!$B$44-AV18)*Params!$B$45,0)-IF(AJ18<0,Params!$B$54,0)-IF(AU18="BREACH",Params!$B$53,0)-IF(T18="DARK",Params!$B$55,0))) | AX18: =IF(AW18<=0,"DEAD",TRIM(IF(V18<0,"OVERWORK ","")&IF(W18<0,"NO-DAYLIGHT ","")&IF(AG18<0,"NO-LOGS ","")&IF(AH18<0,"NO-BOARDS ","")&IF(AI18<0,"NO-FUEL ","")&IF(AJ18<0,"HUNGER ","")&AU18&" "&IF(T18="DARK","DARK-TRIP ","")&IF(AV18<Params!$B$44,"COLD","")))
A19: 11 | B19: =IF(A19<=Params!$B$5,"prep","night") | C19: =MAX(0,A19-Params!$B$5) | D19: =IF(A19<=Params!$B$5,ROUND(Params!$B$7-(Params!$B$7-Params!$B$8)*(A19-1)/(Params!$B$5-1),1),0) | E19: =COUNTIFS(People!$F$2:$F$7,"<="&A19,People!$F$2:$F$7,">0") | F19: =IF(E19=0,1,SUMIFS(People!$C$2:$C$7,People!$F$2:$F$7,"<="&A19,People!$F$2:$F$7,">0")/E19) | G19: =E19*Params!$B$9 | H19: 5.2 | I19: 0 | J19: 2 | K19: 0 | L19: 0 | M19: 0 | R19: =IF(N19="",0,(2*INDEX(Houses!$D$2:$D$18,MATCH(N19,Houses!$A$2:$A$18,0))+Params!$B$57)/IF(O19="",1,INDEX(People!$D$2:$D$7,MATCH(O19,People!$A$2:$A$7,0)))) | S19: =IF(P19="",0,(2*INDEX(Houses!$D$2:$D$18,MATCH(P19,Houses!$A$2:$A$18,0))+Params!$B$57)/IF(Q19="",1,INDEX(People!$D$2:$D$7,MATCH(Q19,People!$A$2:$A$7,0)))) | T19: =IF(AND(N19="",P19=""),"",IF(MAX(R19,S19)<=D19,"ok","DARK")) | U19: =H19+I19+J19+K19*Params!$B$32+L19*Params!$B$34+M19*Params!$B$37+R19+S19 | V19: =G19-U19 | W19: =D19*E19-(H19+R19+S19) | X19: 1 | Y19: =IF(N19="",0,IF(O19="",8,INDEX(People!$E$2:$E$7,MATCH(O19,People!$A$2:$A$7,0)))) | Z19: =IF(N19="",0,MAX(0,MIN(INDEX(Houses!$E$2:$E$18,MATCH(N19,Houses!$A$2:$A$18,0))-IF(INDEX(Houses!$H$2:$H$18,MATCH(N19,Houses!$A$2:$A$18,0))=1,SUMIF($N$8:N18,N19,$Z$8:Z18)+SUMIF($P$8:P18,N19,$AD$8:AD18),0),Y19))) | AA19: =IF(N19="",0,MAX(0,MIN(INDEX(Houses!$F$2:$F$18,MATCH(N19,Houses!$A$2:$A$18,0))-IF(INDEX(Houses!$H$2:$H$18,MATCH(N19,Houses!$A$2:$A$18,0))=1,SUMIF($N$8:N18,N19,$AA$8:AA18)+SUMIF($P$8:P18,N19,$AE$8:AE18),0),INT((Y19-Z19)/2)))) | AB19: =IF(N19="",0,MAX(0,INDEX(Houses!$G$2:$G$18,MATCH(N19,Houses!$A$2:$A$18,0))-IF(INDEX(Houses!$H$2:$H$18,MATCH(N19,Houses!$A$2:$A$18,0))=1,SUMIF($N$8:N18,N19,$AB$8:AB18)+SUMIF($P$8:P18,N19,$AF$8:AF18),0))) | AC19: =IF(P19="",0,IF(Q19="",8,INDEX(People!$E$2:$E$7,MATCH(Q19,People!$A$2:$A$7,0)))) | AD19: =IF(P19="",0,MAX(0,MIN(INDEX(Houses!$E$2:$E$18,MATCH(P19,Houses!$A$2:$A$18,0))-IF(INDEX(Houses!$H$2:$H$18,MATCH(P19,Houses!$A$2:$A$18,0))=1,SUMIF($P$8:P18,P19,$AD$8:AD18)+SUMIF($N$8:N18,P19,$Z$8:Z18)+IF(N19=P19,Z19,0),0),AC19))) | AE19: =IF(P19="",0,MAX(0,MIN(INDEX(Houses!$F$2:$F$18,MATCH(P19,Houses!$A$2:$A$18,0))-IF(INDEX(Houses!$H$2:$H$18,MATCH(P19,Houses!$A$2:$A$18,0))=1,SUMIF($P$8:P18,P19,$AE$8:AE18)+SUMIF($N$8:N18,P19,$AA$8:AA18)+IF(N19=P19,AA19,0),0),INT((AC19-AD19)/2)))) | AF19: =IF(P19="",0,MAX(0,INDEX(Houses!$G$2:$G$18,MATCH(P19,Houses!$A$2:$A$18,0))-IF(INDEX(Houses!$H$2:$H$18,MATCH(P19,Houses!$A$2:$A$18,0))=1,SUMIF($P$8:P18,P19,$AF$8:AF18)+SUMIF($N$8:N18,P19,$AB$8:AB18)+IF(N19=P19,AB19,0),0))) | AG19: =AG18+H19*Params!$B$24*F19-I19*Params!$B$25-J19*Params!$B$27 | AH19: =AH18+I19*Params!$B$25*Params!$B$26-K19*Params!$B$31-L19*Params!$B$33-M19*Params!$B$36+AA19+AE19 | AI19: =AI18+J19*Params!$B$27*Params!$B$28-X19*Params!$B$43*24 | AJ19: =AJ18-E19*Params!$B$22+Z19+AD19 | AK19: =AK18+AB19+AF19 | AL19: =MAX(0,AL18-M19) | AM19: =MAX(0,AT18-K19) | AN19: =AQ18+L19*Params!$B$35 | AO19: =IF(C19=0,0,INDEX(Nights!$B$2:$B$31,C19)) | AP19: =AO19*Params!$B$51*Params!$B$50 | AQ19: =MAX(0,AN19-AP19) | AR19: =INT((AS18+MAX(0,AP19-AN19))/Params!$B$30) | AS19: =(AS18+MAX(0,AP19-AN19))-AR19*Params!$B$30 | AT19: =AM19+AR19 | AU19: =IF(AND(AO19>0,OR(AM19+AL19>0,AR19>0)),"BREACH","") | AV19: =Params!$B$40+IF(AI19<0,0,X19)*Params!$B$41-(AM19+AL19)*Params!$B$42 | AW19: =MAX(0,MIN(100,AW18-IF(AV19<Params!$B$44,(Params!$B$44-AV19)*Params!$B$45,0)-IF(AJ19<0,Params!$B$54,0)-IF(AU19="BREACH",Params!$B$53,0)-IF(T19="DARK",Params!$B$55,0))) | AX19: =IF(AW19<=0,"DEAD",TRIM(IF(V19<0,"OVERWORK ","")&IF(W19<0,"NO-DAYLIGHT ","")&IF(AG19<0,"NO-LOGS ","")&IF(AH19<0,"NO-BOARDS ","")&IF(AI19<0,"NO-FUEL ","")&IF(AJ19<0,"HUNGER ","")&AU19&" "&IF(T19="DARK","DARK-TRIP ","")&IF(AV19<Params!$B$44,"COLD","")))
A20: 12 | B20: =IF(A20<=Params!$B$5,"prep","night") | C20: =MAX(0,A20-Params!$B$5) | D20: =IF(A20<=Params!$B$5,ROUND(Params!$B$7-(Params!$B$7-Params!$B$8)*(A20-1)/(Params!$B$5-1),1),0) | E20: =COUNTIFS(People!$F$2:$F$7,"<="&A20,People!$F$2:$F$7,">0") | F20: =IF(E20=0,1,SUMIFS(People!$C$2:$C$7,People!$F$2:$F$7,"<="&A20,People!$F$2:$F$7,">0")/E20) | G20: =E20*Params!$B$9 | H20: 4.2 | I20: 0 | J20: 1 | K20: 0 | L20: 0 | M20: 0 | R20: =IF(N20="",0,(2*INDEX(Houses!$D$2:$D$18,MATCH(N20,Houses!$A$2:$A$18,0))+Params!$B$57)/IF(O20="",1,INDEX(People!$D$2:$D$7,MATCH(O20,People!$A$2:$A$7,0)))) | S20: =IF(P20="",0,(2*INDEX(Houses!$D$2:$D$18,MATCH(P20,Houses!$A$2:$A$18,0))+Params!$B$57)/IF(Q20="",1,INDEX(People!$D$2:$D$7,MATCH(Q20,People!$A$2:$A$7,0)))) | T20: =IF(AND(N20="",P20=""),"",IF(MAX(R20,S20)<=D20,"ok","DARK")) | U20: =H20+I20+J20+K20*Params!$B$32+L20*Params!$B$34+M20*Params!$B$37+R20+S20 | V20: =G20-U20 | W20: =D20*E20-(H20+R20+S20) | X20: 1 | Y20: =IF(N20="",0,IF(O20="",8,INDEX(People!$E$2:$E$7,MATCH(O20,People!$A$2:$A$7,0)))) | Z20: =IF(N20="",0,MAX(0,MIN(INDEX(Houses!$E$2:$E$18,MATCH(N20,Houses!$A$2:$A$18,0))-IF(INDEX(Houses!$H$2:$H$18,MATCH(N20,Houses!$A$2:$A$18,0))=1,SUMIF($N$8:N19,N20,$Z$8:Z19)+SUMIF($P$8:P19,N20,$AD$8:AD19),0),Y20))) | AA20: =IF(N20="",0,MAX(0,MIN(INDEX(Houses!$F$2:$F$18,MATCH(N20,Houses!$A$2:$A$18,0))-IF(INDEX(Houses!$H$2:$H$18,MATCH(N20,Houses!$A$2:$A$18,0))=1,SUMIF($N$8:N19,N20,$AA$8:AA19)+SUMIF($P$8:P19,N20,$AE$8:AE19),0),INT((Y20-Z20)/2)))) | AB20: =IF(N20="",0,MAX(0,INDEX(Houses!$G$2:$G$18,MATCH(N20,Houses!$A$2:$A$18,0))-IF(INDEX(Houses!$H$2:$H$18,MATCH(N20,Houses!$A$2:$A$18,0))=1,SUMIF($N$8:N19,N20,$AB$8:AB19)+SUMIF($P$8:P19,N20,$AF$8:AF19),0))) | AC20: =IF(P20="",0,IF(Q20="",8,INDEX(People!$E$2:$E$7,MATCH(Q20,People!$A$2:$A$7,0)))) | AD20: =IF(P20="",0,MAX(0,MIN(INDEX(Houses!$E$2:$E$18,MATCH(P20,Houses!$A$2:$A$18,0))-IF(INDEX(Houses!$H$2:$H$18,MATCH(P20,Houses!$A$2:$A$18,0))=1,SUMIF($P$8:P19,P20,$AD$8:AD19)+SUMIF($N$8:N19,P20,$Z$8:Z19)+IF(N20=P20,Z20,0),0),AC20))) | AE20: =IF(P20="",0,MAX(0,MIN(INDEX(Houses!$F$2:$F$18,MATCH(P20,Houses!$A$2:$A$18,0))-IF(INDEX(Houses!$H$2:$H$18,MATCH(P20,Houses!$A$2:$A$18,0))=1,SUMIF($P$8:P19,P20,$AE$8:AE19)+SUMIF($N$8:N19,P20,$AA$8:AA19)+IF(N20=P20,AA20,0),0),INT((AC20-AD20)/2)))) | AF20: =IF(P20="",0,MAX(0,INDEX(Houses!$G$2:$G$18,MATCH(P20,Houses!$A$2:$A$18,0))-IF(INDEX(Houses!$H$2:$H$18,MATCH(P20,Houses!$A$2:$A$18,0))=1,SUMIF($P$8:P19,P20,$AF$8:AF19)+SUMIF($N$8:N19,P20,$AB$8:AB19)+IF(N20=P20,AB20,0),0))) | AG20: =AG19+H20*Params!$B$24*F20-I20*Params!$B$25-J20*Params!$B$27 | AH20: =AH19+I20*Params!$B$25*Params!$B$26-K20*Params!$B$31-L20*Params!$B$33-M20*Params!$B$36+AA20+AE20 | AI20: =AI19+J20*Params!$B$27*Params!$B$28-X20*Params!$B$43*24 | AJ20: =AJ19-E20*Params!$B$22+Z20+AD20 | AK20: =AK19+AB20+AF20 | AL20: =MAX(0,AL19-M20) | AM20: =MAX(0,AT19-K20) | AN20: =AQ19+L20*Params!$B$35 | AO20: =IF(C20=0,0,INDEX(Nights!$B$2:$B$31,C20)) | AP20: =AO20*Params!$B$51*Params!$B$50 | AQ20: =MAX(0,AN20-AP20) | AR20: =INT((AS19+MAX(0,AP20-AN20))/Params!$B$30) | AS20: =(AS19+MAX(0,AP20-AN20))-AR20*Params!$B$30 | AT20: =AM20+AR20 | AU20: =IF(AND(AO20>0,OR(AM20+AL20>0,AR20>0)),"BREACH","") | AV20: =Params!$B$40+IF(AI20<0,0,X20)*Params!$B$41-(AM20+AL20)*Params!$B$42 | AW20: =MAX(0,MIN(100,AW19-IF(AV20<Params!$B$44,(Params!$B$44-AV20)*Params!$B$45,0)-IF(AJ20<0,Params!$B$54,0)-IF(AU20="BREACH",Params!$B$53,0)-IF(T20="DARK",Params!$B$55,0))) | AX20: =IF(AW20<=0,"DEAD",TRIM(IF(V20<0,"OVERWORK ","")&IF(W20<0,"NO-DAYLIGHT ","")&IF(AG20<0,"NO-LOGS ","")&IF(AH20<0,"NO-BOARDS ","")&IF(AI20<0,"NO-FUEL ","")&IF(AJ20<0,"HUNGER ","")&AU20&" "&IF(T20="DARK","DARK-TRIP ","")&IF(AV20<Params!$B$44,"COLD","")))
A21: 13 | B21: =IF(A21<=Params!$B$5,"prep","night") | C21: =MAX(0,A21-Params!$B$5) | D21: =IF(A21<=Params!$B$5,ROUND(Params!$B$7-(Params!$B$7-Params!$B$8)*(A21-1)/(Params!$B$5-1),1),0) | E21: =COUNTIFS(People!$F$2:$F$7,"<="&A21,People!$F$2:$F$7,">0") | F21: =IF(E21=0,1,SUMIFS(People!$C$2:$C$7,People!$F$2:$F$7,"<="&A21,People!$F$2:$F$7,">0")/E21) | G21: =E21*Params!$B$9 | H21: 3 | I21: 0 | J21: 1 | K21: 0 | L21: 0 | M21: 0 | R21: =IF(N21="",0,(2*INDEX(Houses!$D$2:$D$18,MATCH(N21,Houses!$A$2:$A$18,0))+Params!$B$57)/IF(O21="",1,INDEX(People!$D$2:$D$7,MATCH(O21,People!$A$2:$A$7,0)))) | S21: =IF(P21="",0,(2*INDEX(Houses!$D$2:$D$18,MATCH(P21,Houses!$A$2:$A$18,0))+Params!$B$57)/IF(Q21="",1,INDEX(People!$D$2:$D$7,MATCH(Q21,People!$A$2:$A$7,0)))) | T21: =IF(AND(N21="",P21=""),"",IF(MAX(R21,S21)<=D21,"ok","DARK")) | U21: =H21+I21+J21+K21*Params!$B$32+L21*Params!$B$34+M21*Params!$B$37+R21+S21 | V21: =G21-U21 | W21: =D21*E21-(H21+R21+S21) | X21: 1 | Y21: =IF(N21="",0,IF(O21="",8,INDEX(People!$E$2:$E$7,MATCH(O21,People!$A$2:$A$7,0)))) | Z21: =IF(N21="",0,MAX(0,MIN(INDEX(Houses!$E$2:$E$18,MATCH(N21,Houses!$A$2:$A$18,0))-IF(INDEX(Houses!$H$2:$H$18,MATCH(N21,Houses!$A$2:$A$18,0))=1,SUMIF($N$8:N20,N21,$Z$8:Z20)+SUMIF($P$8:P20,N21,$AD$8:AD20),0),Y21))) | AA21: =IF(N21="",0,MAX(0,MIN(INDEX(Houses!$F$2:$F$18,MATCH(N21,Houses!$A$2:$A$18,0))-IF(INDEX(Houses!$H$2:$H$18,MATCH(N21,Houses!$A$2:$A$18,0))=1,SUMIF($N$8:N20,N21,$AA$8:AA20)+SUMIF($P$8:P20,N21,$AE$8:AE20),0),INT((Y21-Z21)/2)))) | AB21: =IF(N21="",0,MAX(0,INDEX(Houses!$G$2:$G$18,MATCH(N21,Houses!$A$2:$A$18,0))-IF(INDEX(Houses!$H$2:$H$18,MATCH(N21,Houses!$A$2:$A$18,0))=1,SUMIF($N$8:N20,N21,$AB$8:AB20)+SUMIF($P$8:P20,N21,$AF$8:AF20),0))) | AC21: =IF(P21="",0,IF(Q21="",8,INDEX(People!$E$2:$E$7,MATCH(Q21,People!$A$2:$A$7,0)))) | AD21: =IF(P21="",0,MAX(0,MIN(INDEX(Houses!$E$2:$E$18,MATCH(P21,Houses!$A$2:$A$18,0))-IF(INDEX(Houses!$H$2:$H$18,MATCH(P21,Houses!$A$2:$A$18,0))=1,SUMIF($P$8:P20,P21,$AD$8:AD20)+SUMIF($N$8:N20,P21,$Z$8:Z20)+IF(N21=P21,Z21,0),0),AC21))) | AE21: =IF(P21="",0,MAX(0,MIN(INDEX(Houses!$F$2:$F$18,MATCH(P21,Houses!$A$2:$A$18,0))-IF(INDEX(Houses!$H$2:$H$18,MATCH(P21,Houses!$A$2:$A$18,0))=1,SUMIF($P$8:P20,P21,$AE$8:AE20)+SUMIF($N$8:N20,P21,$AA$8:AA20)+IF(N21=P21,AA21,0),0),INT((AC21-AD21)/2)))) | AF21: =IF(P21="",0,MAX(0,INDEX(Houses!$G$2:$G$18,MATCH(P21,Houses!$A$2:$A$18,0))-IF(INDEX(Houses!$H$2:$H$18,MATCH(P21,Houses!$A$2:$A$18,0))=1,SUMIF($P$8:P20,P21,$AF$8:AF20)+SUMIF($N$8:N20,P21,$AB$8:AB20)+IF(N21=P21,AB21,0),0))) | AG21: =AG20+H21*Params!$B$24*F21-I21*Params!$B$25-J21*Params!$B$27 | AH21: =AH20+I21*Params!$B$25*Params!$B$26-K21*Params!$B$31-L21*Params!$B$33-M21*Params!$B$36+AA21+AE21 | AI21: =AI20+J21*Params!$B$27*Params!$B$28-X21*Params!$B$43*24 | AJ21: =AJ20-E21*Params!$B$22+Z21+AD21 | AK21: =AK20+AB21+AF21 | AL21: =MAX(0,AL20-M21) | AM21: =MAX(0,AT20-K21) | AN21: =AQ20+L21*Params!$B$35 | AO21: =IF(C21=0,0,INDEX(Nights!$B$2:$B$31,C21)) | AP21: =AO21*Params!$B$51*Params!$B$50 | AQ21: =MAX(0,AN21-AP21) | AR21: =INT((AS20+MAX(0,AP21-AN21))/Params!$B$30) | AS21: =(AS20+MAX(0,AP21-AN21))-AR21*Params!$B$30 | AT21: =AM21+AR21 | AU21: =IF(AND(AO21>0,OR(AM21+AL21>0,AR21>0)),"BREACH","") | AV21: =Params!$B$40+IF(AI21<0,0,X21)*Params!$B$41-(AM21+AL21)*Params!$B$42 | AW21: =MAX(0,MIN(100,AW20-IF(AV21<Params!$B$44,(Params!$B$44-AV21)*Params!$B$45,0)-IF(AJ21<0,Params!$B$54,0)-IF(AU21="BREACH",Params!$B$53,0)-IF(T21="DARK",Params!$B$55,0))) | AX21: =IF(AW21<=0,"DEAD",TRIM(IF(V21<0,"OVERWORK ","")&IF(W21<0,"NO-DAYLIGHT ","")&IF(AG21<0,"NO-LOGS ","")&IF(AH21<0,"NO-BOARDS ","")&IF(AI21<0,"NO-FUEL ","")&IF(AJ21<0,"HUNGER ","")&AU21&" "&IF(T21="DARK","DARK-TRIP ","")&IF(AV21<Params!$B$44,"COLD","")))
A22: 14 | B22: =IF(A22<=Params!$B$5,"prep","night") | C22: =MAX(0,A22-Params!$B$5) | D22: =IF(A22<=Params!$B$5,ROUND(Params!$B$7-(Params!$B$7-Params!$B$8)*(A22-1)/(Params!$B$5-1),1),0) | E22: =COUNTIFS(People!$F$2:$F$7,"<="&A22,People!$F$2:$F$7,">0") | F22: =IF(E22=0,1,SUMIFS(People!$C$2:$C$7,People!$F$2:$F$7,"<="&A22,People!$F$2:$F$7,">0")/E22) | G22: =E22*Params!$B$9 | H22: 2 | I22: 0 | J22: 2 | K22: 0 | L22: 0 | M22: 0 | R22: =IF(N22="",0,(2*INDEX(Houses!$D$2:$D$18,MATCH(N22,Houses!$A$2:$A$18,0))+Params!$B$57)/IF(O22="",1,INDEX(People!$D$2:$D$7,MATCH(O22,People!$A$2:$A$7,0)))) | S22: =IF(P22="",0,(2*INDEX(Houses!$D$2:$D$18,MATCH(P22,Houses!$A$2:$A$18,0))+Params!$B$57)/IF(Q22="",1,INDEX(People!$D$2:$D$7,MATCH(Q22,People!$A$2:$A$7,0)))) | T22: =IF(AND(N22="",P22=""),"",IF(MAX(R22,S22)<=D22,"ok","DARK")) | U22: =H22+I22+J22+K22*Params!$B$32+L22*Params!$B$34+M22*Params!$B$37+R22+S22 | V22: =G22-U22 | W22: =D22*E22-(H22+R22+S22) | X22: 1 | Y22: =IF(N22="",0,IF(O22="",8,INDEX(People!$E$2:$E$7,MATCH(O22,People!$A$2:$A$7,0)))) | Z22: =IF(N22="",0,MAX(0,MIN(INDEX(Houses!$E$2:$E$18,MATCH(N22,Houses!$A$2:$A$18,0))-IF(INDEX(Houses!$H$2:$H$18,MATCH(N22,Houses!$A$2:$A$18,0))=1,SUMIF($N$8:N21,N22,$Z$8:Z21)+SUMIF($P$8:P21,N22,$AD$8:AD21),0),Y22))) | AA22: =IF(N22="",0,MAX(0,MIN(INDEX(Houses!$F$2:$F$18,MATCH(N22,Houses!$A$2:$A$18,0))-IF(INDEX(Houses!$H$2:$H$18,MATCH(N22,Houses!$A$2:$A$18,0))=1,SUMIF($N$8:N21,N22,$AA$8:AA21)+SUMIF($P$8:P21,N22,$AE$8:AE21),0),INT((Y22-Z22)/2)))) | AB22: =IF(N22="",0,MAX(0,INDEX(Houses!$G$2:$G$18,MATCH(N22,Houses!$A$2:$A$18,0))-IF(INDEX(Houses!$H$2:$H$18,MATCH(N22,Houses!$A$2:$A$18,0))=1,SUMIF($N$8:N21,N22,$AB$8:AB21)+SUMIF($P$8:P21,N22,$AF$8:AF21),0))) | AC22: =IF(P22="",0,IF(Q22="",8,INDEX(People!$E$2:$E$7,MATCH(Q22,People!$A$2:$A$7,0)))) | AD22: =IF(P22="",0,MAX(0,MIN(INDEX(Houses!$E$2:$E$18,MATCH(P22,Houses!$A$2:$A$18,0))-IF(INDEX(Houses!$H$2:$H$18,MATCH(P22,Houses!$A$2:$A$18,0))=1,SUMIF($P$8:P21,P22,$AD$8:AD21)+SUMIF($N$8:N21,P22,$Z$8:Z21)+IF(N22=P22,Z22,0),0),AC22))) | AE22: =IF(P22="",0,MAX(0,MIN(INDEX(Houses!$F$2:$F$18,MATCH(P22,Houses!$A$2:$A$18,0))-IF(INDEX(Houses!$H$2:$H$18,MATCH(P22,Houses!$A$2:$A$18,0))=1,SUMIF($P$8:P21,P22,$AE$8:AE21)+SUMIF($N$8:N21,P22,$AA$8:AA21)+IF(N22=P22,AA22,0),0),INT((AC22-AD22)/2)))) | AF22: =IF(P22="",0,MAX(0,INDEX(Houses!$G$2:$G$18,MATCH(P22,Houses!$A$2:$A$18,0))-IF(INDEX(Houses!$H$2:$H$18,MATCH(P22,Houses!$A$2:$A$18,0))=1,SUMIF($P$8:P21,P22,$AF$8:AF21)+SUMIF($N$8:N21,P22,$AB$8:AB21)+IF(N22=P22,AB22,0),0))) | AG22: =AG21+H22*Params!$B$24*F22-I22*Params!$B$25-J22*Params!$B$27 | AH22: =AH21+I22*Params!$B$25*Params!$B$26-K22*Params!$B$31-L22*Params!$B$33-M22*Params!$B$36+AA22+AE22 | AI22: =AI21+J22*Params!$B$27*Params!$B$28-X22*Params!$B$43*24 | AJ22: =AJ21-E22*Params!$B$22+Z22+AD22 | AK22: =AK21+AB22+AF22 | AL22: =MAX(0,AL21-M22) | AM22: =MAX(0,AT21-K22) | AN22: =AQ21+L22*Params!$B$35 | AO22: =IF(C22=0,0,INDEX(Nights!$B$2:$B$31,C22)) | AP22: =AO22*Params!$B$51*Params!$B$50 | AQ22: =MAX(0,AN22-AP22) | AR22: =INT((AS21+MAX(0,AP22-AN22))/Params!$B$30) | AS22: =(AS21+MAX(0,AP22-AN22))-AR22*Params!$B$30 | AT22: =AM22+AR22 | AU22: =IF(AND(AO22>0,OR(AM22+AL22>0,AR22>0)),"BREACH","") | AV22: =Params!$B$40+IF(AI22<0,0,X22)*Params!$B$41-(AM22+AL22)*Params!$B$42 | AW22: =MAX(0,MIN(100,AW21-IF(AV22<Params!$B$44,(Params!$B$44-AV22)*Params!$B$45,0)-IF(AJ22<0,Params!$B$54,0)-IF(AU22="BREACH",Params!$B$53,0)-IF(T22="DARK",Params!$B$55,0))) | AX22: =IF(AW22<=0,"DEAD",TRIM(IF(V22<0,"OVERWORK ","")&IF(W22<0,"NO-DAYLIGHT ","")&IF(AG22<0,"NO-LOGS ","")&IF(AH22<0,"NO-BOARDS ","")&IF(AI22<0,"NO-FUEL ","")&IF(AJ22<0,"HUNGER ","")&AU22&" "&IF(T22="DARK","DARK-TRIP ","")&IF(AV22<Params!$B$44,"COLD","")))
A23: 15 | B23: =IF(A23<=Params!$B$5,"prep","night") | C23: =MAX(0,A23-Params!$B$5) | D23: =IF(A23<=Params!$B$5,ROUND(Params!$B$7-(Params!$B$7-Params!$B$8)*(A23-1)/(Params!$B$5-1),1),0) | E23: =COUNTIFS(People!$F$2:$F$7,"<="&A23,People!$F$2:$F$7,">0") | F23: =IF(E23=0,1,SUMIFS(People!$C$2:$C$7,People!$F$2:$F$7,"<="&A23,People!$F$2:$F$7,">0")/E23) | G23: =E23*Params!$B$9 | H23: 0 | I23: 0 | J23: 1 | K23: 0 | L23: 3 | M23: 0 | R23: =IF(N23="",0,(2*INDEX(Houses!$D$2:$D$18,MATCH(N23,Houses!$A$2:$A$18,0))+Params!$B$57)/IF(O23="",1,INDEX(People!$D$2:$D$7,MATCH(O23,People!$A$2:$A$7,0)))) | S23: =IF(P23="",0,(2*INDEX(Houses!$D$2:$D$18,MATCH(P23,Houses!$A$2:$A$18,0))+Params!$B$57)/IF(Q23="",1,INDEX(People!$D$2:$D$7,MATCH(Q23,People!$A$2:$A$7,0)))) | T23: =IF(AND(N23="",P23=""),"",IF(MAX(R23,S23)<=D23,"ok","DARK")) | U23: =H23+I23+J23+K23*Params!$B$32+L23*Params!$B$34+M23*Params!$B$37+R23+S23 | V23: =G23-U23 | W23: =D23*E23-(H23+R23+S23) | X23: 1 | Y23: =IF(N23="",0,IF(O23="",8,INDEX(People!$E$2:$E$7,MATCH(O23,People!$A$2:$A$7,0)))) | Z23: =IF(N23="",0,MAX(0,MIN(INDEX(Houses!$E$2:$E$18,MATCH(N23,Houses!$A$2:$A$18,0))-IF(INDEX(Houses!$H$2:$H$18,MATCH(N23,Houses!$A$2:$A$18,0))=1,SUMIF($N$8:N22,N23,$Z$8:Z22)+SUMIF($P$8:P22,N23,$AD$8:AD22),0),Y23))) | AA23: =IF(N23="",0,MAX(0,MIN(INDEX(Houses!$F$2:$F$18,MATCH(N23,Houses!$A$2:$A$18,0))-IF(INDEX(Houses!$H$2:$H$18,MATCH(N23,Houses!$A$2:$A$18,0))=1,SUMIF($N$8:N22,N23,$AA$8:AA22)+SUMIF($P$8:P22,N23,$AE$8:AE22),0),INT((Y23-Z23)/2)))) | AB23: =IF(N23="",0,MAX(0,INDEX(Houses!$G$2:$G$18,MATCH(N23,Houses!$A$2:$A$18,0))-IF(INDEX(Houses!$H$2:$H$18,MATCH(N23,Houses!$A$2:$A$18,0))=1,SUMIF($N$8:N22,N23,$AB$8:AB22)+SUMIF($P$8:P22,N23,$AF$8:AF22),0))) | AC23: =IF(P23="",0,IF(Q23="",8,INDEX(People!$E$2:$E$7,MATCH(Q23,People!$A$2:$A$7,0)))) | AD23: =IF(P23="",0,MAX(0,MIN(INDEX(Houses!$E$2:$E$18,MATCH(P23,Houses!$A$2:$A$18,0))-IF(INDEX(Houses!$H$2:$H$18,MATCH(P23,Houses!$A$2:$A$18,0))=1,SUMIF($P$8:P22,P23,$AD$8:AD22)+SUMIF($N$8:N22,P23,$Z$8:Z22)+IF(N23=P23,Z23,0),0),AC23))) | AE23: =IF(P23="",0,MAX(0,MIN(INDEX(Houses!$F$2:$F$18,MATCH(P23,Houses!$A$2:$A$18,0))-IF(INDEX(Houses!$H$2:$H$18,MATCH(P23,Houses!$A$2:$A$18,0))=1,SUMIF($P$8:P22,P23,$AE$8:AE22)+SUMIF($N$8:N22,P23,$AA$8:AA22)+IF(N23=P23,AA23,0),0),INT((AC23-AD23)/2)))) | AF23: =IF(P23="",0,MAX(0,INDEX(Houses!$G$2:$G$18,MATCH(P23,Houses!$A$2:$A$18,0))-IF(INDEX(Houses!$H$2:$H$18,MATCH(P23,Houses!$A$2:$A$18,0))=1,SUMIF($P$8:P22,P23,$AF$8:AF22)+SUMIF($N$8:N22,P23,$AB$8:AB22)+IF(N23=P23,AB23,0),0))) | AG23: =AG22+H23*Params!$B$24*F23-I23*Params!$B$25-J23*Params!$B$27 | AH23: =AH22+I23*Params!$B$25*Params!$B$26-K23*Params!$B$31-L23*Params!$B$33-M23*Params!$B$36+AA23+AE23 | AI23: =AI22+J23*Params!$B$27*Params!$B$28-X23*Params!$B$43*24 | AJ23: =AJ22-E23*Params!$B$22+Z23+AD23 | AK23: =AK22+AB23+AF23 | AL23: =MAX(0,AL22-M23) | AM23: =MAX(0,AT22-K23) | AN23: =AQ22+L23*Params!$B$35 | AO23: =IF(C23=0,0,INDEX(Nights!$B$2:$B$31,C23)) | AP23: =AO23*Params!$B$51*Params!$B$50 | AQ23: =MAX(0,AN23-AP23) | AR23: =INT((AS22+MAX(0,AP23-AN23))/Params!$B$30) | AS23: =(AS22+MAX(0,AP23-AN23))-AR23*Params!$B$30 | AT23: =AM23+AR23 | AU23: =IF(AND(AO23>0,OR(AM23+AL23>0,AR23>0)),"BREACH","") | AV23: =Params!$B$40+IF(AI23<0,0,X23)*Params!$B$41-(AM23+AL23)*Params!$B$42 | AW23: =MAX(0,MIN(100,AW22-IF(AV23<Params!$B$44,(Params!$B$44-AV23)*Params!$B$45,0)-IF(AJ23<0,Params!$B$54,0)-IF(AU23="BREACH",Params!$B$53,0)-IF(T23="DARK",Params!$B$55,0))) | AX23: =IF(AW23<=0,"DEAD",TRIM(IF(V23<0,"OVERWORK ","")&IF(W23<0,"NO-DAYLIGHT ","")&IF(AG23<0,"NO-LOGS ","")&IF(AH23<0,"NO-BOARDS ","")&IF(AI23<0,"NO-FUEL ","")&IF(AJ23<0,"HUNGER ","")&AU23&" "&IF(T23="DARK","DARK-TRIP ","")&IF(AV23<Params!$B$44,"COLD","")))
